Workbook

Sheet FDC
A1: MDN
A2: 29.11.2025 au jsp
A3: Fonds de caisse et comptage gain par jour
A5: samedi | B5: 45990 | F5: dimanche | G5: =B5+1 -> 45991 | K5: lundi | L5: =G5+1 -> 45992 | P5: mardi | Q5: =L5+1 -> 45993 | U5: Mercedi | V5: =Q5+1 -> 45994 | Y5: Jeudi | Z5: =V5+1 -> 45995 | AC5: vendredi | AD5: =Z5+1 -> 45996 | AG5: samedi | AH5: =AD5+1 -> 45997 | AK5: dimanche | AL5: =AH5+1 -> 45998 | AO5: Dimanche | AP5: =AL5+1 -> 45999
A6: FDC
A7: Monnaies | B7: NB | C7: ajout | D7: Tot | F7: Monnaies | G7: NB | H7: ajout | I7: Tot | K7: Monnaies | L7: NB | M7: ajout | N7: Tot | P7: Monnaies | Q7: NB | R7: ajout | S7: Tot | U7: Monnaies | V7: NB | W7: ajout | X7: Tot | Y7: Monnaies | Z7: NB | AA7: ajout | AB7: Tot | AC7: Monnaies | AD7: NB | AE7: ajout | AF7: Tot | AG7: Monnaies | AH7: NB | AI7: ajout | AJ7: Tot | AK7: Monnaies | AL7: NB | AM7: ajout | AN7: Tot | AO7: Monnaies | AP7: NB | AQ7: ajout | AR7: Tot
A8: 200 | G8: 0 | K8: 200 | L8: 0 | Q8: 0
A9: 100 | B9: 1 | D9: =A9*(B9+C9) -> 100 | F9: 100 | G9: 3 | H9: -2 | I9: =F9*(G9+H9) -> 100 | K9: 100 | L9: 2 | M9: -1 | N9: =K9*(L9+M9) -> 100 | P9: 100 | Q9: 2 | R9: -1 | S9: =P9*(Q9+R9) -> 100 | U9: 100 | V9: 1 | X9: =U9*(V9+W9) -> 100 | Y9: 100 | Z9: 1 | AB9: =Y9*(Z9+AA9) -> 100 | AC9: 100 | AD9: 2 | AF9: =AC9*(AD9+AE9) -> 200 | AG9: 100 | AH9: 6 | AI9: -5 | AJ9: =AG9*(AH9+AI9) -> 100 | AK9: 100 | AL9: 2 | AM9: -1 | AN9: =AK9*(AL9+AM9) -> 100 | AO9: 100 | AR9: =AO9*(AP9+AQ9) -> 0
A10: 50 | B10: 3 | D10: =A10*(B10+C10) -> 150 | F10: 50 | G10: 10 | H10: -7 | I10: =F10*(G10+H10) -> 150 | K10: 50 | L10: 3 | N10: =K10*(L10+M10) -> 150 | P10: 50 | Q10: 4 | R10: -1 | S10: =P10*(Q10+R10) -> 150 | U10: 50 | V10: 3 | X10: =U10*(V10+W10) -> 150 | Y10: 50 | Z10: 5 | AA10: -2 | AB10: =Y10*(Z10+AA10) -> 150 | AC10: 50 | AD10: 4 | AF10: =AC10*(AD10+AE10) -> 200 | AG10: 50 | AH10: 8 | AI10: -5 | AJ10: =AG10*(AH10+AI10) -> 150 | AK10: 50 | AL10: 9 | AM10: -4 | AN10: =AK10*(AL10+AM10) -> 250 | AO10: 50 | AR10: =AO10*(AP10+AQ10) -> 0
A11: 20 | B11: 10 | D11: =A11*(B11+C11) -> 200 | F11: 20 | G11: 19 | H11: -10 | I11: =F11*(G11+H11) -> 180 | K11: 20 | L11: 17 | M11: -7 | N11: =K11*(L11+M11) -> 200 | P11: 20 | Q11: 13 | R11: -3 | S11: =P11*(Q11+R11) -> 200 | U11: 20 | V11: 15 | W11: -4 | X11: =U11*(V11+W11) -> 220 | Y11: 20 | Z11: 12 | AA11: -2 | AB11: =Y11*(Z11+AA11) -> 200 | AC11: 20 | AD11: 9 | AF11: =AC11*(AD11+AE11) -> 180 | AG11: 20 | AH11: 21 | AI11: -11 | AJ11: =AG11*(AH11+AI11) -> 200 | AK11: 20 | AL11: 18 | AM11: -5 | AN11: =AK11*(AL11+AM11) -> 260 | AO11: 20 | AR11: =AO11*(AP11+AQ11) -> 0
A12: 10 | B12: 9 | D12: =A12*(B12+C12) -> 90 | F12: 10 | G12: 17 | H12: -9 | I12: =F12*(G12+H12) -> 80 | K12: 10 | L12: 7 | N12: =K12*(L12+M12) -> 70 | P12: 10 | Q12: 5 | R12: 5 | S12: =P12*(Q12+R12) -> 100 | U12: 10 | V12: 9 | X12: =U12*(V12+W12) -> 90 | Y12: 10 | Z12: 5 | AB12: =Y12*(Z12+AA12) -> 50 | AC12: 10 | AD12: 7 | AE12: =2 -> 2 | AF12: =AC12*(AD12+AE12) -> 90 | AG12: 10 | AH12: 7 | AJ12: =AG12*(AH12+AI12) -> 70 | AK12: 10 | AL12: 4 | AN12: =AK12*(AL12+AM12) -> 40 | AO12: 10 | AR12: =AO12*(AP12+AQ12) -> 0
A13: 5 | B13: 25 | D13: =A13*(B13+C13) -> 125 | F13: 5 | G13: 13 | I13: =F13*(G13+H13) -> 65 | K13: 5 | L13: 9 | N13: =K13*(L13+M13) -> 45 | P13: 5 | Q13: 6 | S13: =P13*(Q13+R13) -> 30 | U13: 5 | V13: 11 | X13: =U13*(V13+W13) -> 55 | Y13: 5 | Z13: 6 | AA13: 4 | AB13: =Y13*(Z13+AA13) -> 50 | AC13: 5 | AD13: 9 | AF13: =AC13*(AD13+AE13) -> 45 | AG13: 5 | AH13: 0 | AI13: 6 | AJ13: =AG13*(AH13+AI13) -> 30 | AK13: 5 | AL13: 0 | AN13: =AK13*(AL13+AM13) -> 0 | AO13: 5 | AR13: =AO13*(AP13+AQ13) -> 0
A14: 2 | B14: 275 | D14: =A14*(B14+C14) -> 550 | F14: 2 | G14: 190 | H14: 0 | I14: =F14*(G14+H14) -> 380 | K14: 2 | L14: 162 | N14: =K14*(L14+M14) -> 324 | P14: 2 | Q14: 144 | S14: =P14*(Q14+R14) -> 288 | U14: 2 | V14: 123 | X14: =U14*(V14+W14) -> 246 | Y14: 2 | Z14: 104 | AB14: =Y14*(Z14+AA14) -> 208 | AC14: 2 | AD14: 64 | AE14: 50 | AF14: =AC14*(AD14+AE14) -> 228 | AG14: 2 | AH14: 60 | AI14: 150 | AJ14: =AG14*(AH14+AI14) -> 420 | AK14: 2 | AL14: 131 | AN14: =AK14*(AL14+AM14) -> 262 | AO14: 2 | AR14: =AO14*(AP14+AQ14) -> 0
A15: 1 | B15: 150 | D15: =A15*(B15+C15) -> 150 | F15: 1 | G15: 129 | H15: 0 | I15: =F15*(G15+H15) -> 129 | K15: 1 | L15: 84 | N15: =K15*(L15+M15) -> 84 | P15: 1 | Q15: 65 | S15: =P15*(Q15+R15) -> 65 | U15: 1 | V15: 65 | X15: =U15*(V15+W15) -> 65 | Y15: 1 | Z15: 39 | AB15: =Y15*(Z15+AA15) -> 39 | AC15: 1 | AD15: 33 | AF15: =AC15*(AD15+AE15) -> 33 | AG15: 1 | AH15: 23 | AI15: 22 | AJ15: =AG15*(AH15+AI15) -> 45 | AK15: 1 | AL15: 16 | AN15: =AK15*(AL15+AM15) -> 16 | AO15: 1 | AR15: =AO15*(AP15+AQ15) -> 0
A16: 0.5 | B16: 50 | D16: =A16*(B16+C16) -> 25 | F16: 0.5 | G16: 53 | I16: =F16*(G16+H16) -> 26.5 | K16: 0.5 | L16: 51 | N16: =K16*(L16+M16) -> 25.5 | P16: 0.5 | Q16: 51 | S16: =P16*(Q16+R16) -> 25.5 | U16: 0.5 | V16: 49 | X16: =U16*(V16+W16) -> 24.5 | Y16: 0.5 | Z16: 45 | AB16: =Y16*(Z16+AA16) -> 22.5 | AC16: 0.5 | AD16: 47 | AF16: =AC16*(AD16+AE16) -> 23.5 | AG16: 0.5 | AH16: 48 | AJ16: =AG16*(AH16+AI16) -> 24 | AK16: 0.5 | AL16: 49 | AN16: =AK16*(AL16+AM16) -> 24.5 | AO16: 0.5 | AR16: =AO16*(AP16+AQ16) -> 0
A17: 0.2 | D17: =A17*(B17+C17) -> 0 | F17: 0.2 | G17: 12 | I17: =F17*(G17+H17) -> 2.4 | K17: 0.2 | L17: 12 | N17: =K17*(L17+M17) -> 2.4 | P17: 0.2 | Q17: 12 | S17: =P17*(Q17+R17) -> 2.4 | U17: 0.2 | V17: 10 | X17: =U17*(V17+W17) -> 2 | Y17: 0.2 | Z17: 11 | AB17: =Y17*(Z17+AA17) -> 2.2 | AC17: 0.2 | AD17: 11 | AF17: =AC17*(AD17+AE17) -> 2.2 | AG17: 0.2 | AH17: 11 | AJ17: =AG17*(AH17+AI17) -> 2.2 | AK17: 0.2 | AL17: 15 | AN17: =AK17*(AL17+AM17) -> 3 | AO17: 0.2 | AR17: =AO17*(AP17+AQ17) -> 0
A18: 0.1 | D18: =A18*(B18+C18) -> 0 | F18: 0.1 | G18: 11 | I18: =F18*(G18+H18) -> 1.1 | K18: 0.1 | L18: 11 | N18: =K18*(L18+M18) -> 1.1 | P18: 0.1 | Q18: 11 | S18: =P18*(Q18+R18) -> 1.1 | U18: 0.1 | V18: 11 | X18: =U18*(V18+W18) -> 1.1 | Y18: 0.1 | Z18: 11 | AB18: =Y18*(Z18+AA18) -> 1.1 | AC18: 0.1 | AD18: 11 | AF18: =AC18*(AD18+AE18) -> 1.1 | AG18: 0.1 | AH18: 11 | AJ18: =AG18*(AH18+AI18) -> 1.1 | AK18: 0.1 | AL18: 12 | AN18: =AK18*(AL18+AM18) -> 1.2 | AO18: 0.1 | AR18: =AO18*(AP18+AQ18) -> 0
A19: 0.05 | D19: =A19*(B19+C19) -> 0 | F19: 0.05 | G19: 0 | I19: =F19*(G19+H19) -> 0 | K19: 0.05 | L19: 0 | N19: =K19*(L19+M19) -> 0 | P19: 0.05 | Q19: 0 | S19: =P19*(Q19+R19) -> 0 | U19: 0.05 | V19: 0 | X19: =U19*(V19+W19) -> 0 | Y19: 0.05 | Z19: 0 | AB19: =Y19*(Z19+AA19) -> 0 | AC19: 0.05 | AD19: 0 | AF19: =AC19*(AD19+AE19) -> 0 | AG19: 0.05 | AH19: 1 | AJ19: =AG19*(AH19+AI19) -> 0.05 | AK19: 0.05 | AL19: 1 | AN19: =AK19*(AL19+AM19) -> 0.05 | AO19: 0.05 | AR19: =AO19*(AP19+AQ19) -> 0
V20: 0 | Z20: 0 | AD20: 0 | AH20: 0 | AL20: 0
A21: Total fdc | D21: =SUM(D8:D19) -> 1390 | F21: Total fdc | I21: =SUM(I9:I20) -> 1114 | K21: Total fdc | N21: =SUM(N9:N19) -> 1002 | P21: Total fdc | S21: =SUM(S9:S19) -> 962 | U21: Total fdc | X21: =SUM(X9:X19) -> 953.6 | Y21: Total fdc | AB21: =SUM(AB9:AB19) -> 822.8 | AC21: Total fdc | AF21: =SUM(AF9:AF19) -> 1002.8 | AG21: Total fdc | AJ21: =SUM(AJ9:AJ19) -> 1042.35 | AK21: Total fdc | AN21: =SUM(AN9:AN19) -> 956.75 | AO21: Total fdc | AR21: =SUM(AR9:AR19) -> 0
A24: Gains | D24: =D41-D21 -> 564 | F24: Gains | I24: =I41-I21 -> 128 | K24: Gains | N24: =N41-N21 -> 120 | P24: Gains | S24: =S41-S21 -> 71.6 | U24: Gains | X24: =X41-X21 -> -10.8 | Y24: Gains | AB24: =AB41-AB21 -> 60 | AC24: Gains | AF24: =AF41-AF21 -> 657.55 | AG24: Gains | AJ24: =AJ41-AJ21 -> 314.4 | AK24: Gains | AN24: =AN41-AN21 -> 81.05 | AO24: Gains | AR24: =AR41-AR21 -> 0
A26: Comptages clôture de chaque jours de ventes
A27: Monnaies | B27: NB | C27: ajout | D27: Tot | F27: Monnaies | G27: NB | H27: ajout | I27: Tot | K27: Monnaies | L27: NB | M27: ajout | N27: Tot | P27: Monnaies | Q27: NB | R27: ajout | S27: Tot | U27: Monnaies | V27: NB | W27: ajout | X27: Tot | Y27: Monnaies | Z27: NB | AA27: ajout | AB27: Tot | AC27: Monnaies | AD27: NB | AE27: ajout | AF27: Tot | AG27: Monnaies | AH27: NB | AI27: ajout | AJ27: Tot | AK27: Monnaies | AL27: NB | AM27: ajout | AN27: Tot | AO27: Monnaies | AP27: NB | AQ27: ajout | AR27: Tot
A28: 200 | B28: 0 | D28: =A28*(B28+C28) -> 0 | F28: 200 | G28: 0 | I28: =G28*F28 -> 0 | L28: 0 | Q28: 0 | U28: 200 | V28: 0 | X28: =U28*V28 -> 0 | Y28: 200 | Z28: 0 | AB28: =Y28*Z28 -> 0 | AC28: 200 | AD28: 0 | AF28: =AC28*(AD28+AE28) -> 0 | AG28: 200 | AH28: 0 | AJ28: =AG28*(AH28+AI28) -> 0 | AK28: 200 | AL28: 1 | AN28: =AK28*(AL28+AM28) -> 200 | AO28: 200 | AR28: =AO28*(AP28+AQ28) -> 0
A29: 100 | B29: 3 | D29: =A29*(B29+C29) -> 300 | F29: 100 | G29: 2 | I29: =F29*(G29+H29) -> 200 | K29: 100 | L29: 2 | N29: =K29*(L29+M29) -> 200 | P29: 100 | Q29: 1 | S29: =P29*(Q29+R29) -> 100 | U29: 100 | V29: 1 | X29: =U29*(V29+W29) -> 100 | Y29: 100 | Z29: 2 | AB29: =Y29*(Z29+AA29) -> 200 | AC29: 100 | AD29: 6 | AF29: =AC29*(AD29+AE29) -> 600 | AG29: 100 | AH29: 2 | AJ29: =AG29*(AH29+AI29) -> 200 | AK29: 100 | AL29: 1 | AN29: =AK29*(AL29+AM29) -> 100 | AO29: 100 | AR29: =AO29*(AP29+AQ29) -> 0
A30: 50 | B30: 10 | D30: =A30*(B30+C30) -> 500 | F30: 50 | G30: 3 | I30: =F30*(G30+H30) -> 150 | K30: 50 | L30: 4 | N30: =K30*(L30) -> 200 | P30: 50 | Q30: 3 | S30: =P30*(Q30+R30) -> 150 | U30: 50 | V30: 5 | X30: =U30*(V30+W30) -> 250 | Y30: 50 | Z30: 4 | AB30: =Y30*(Z30+AA30) -> 200 | AC30: 50 | AD30: 8 | AF30: =AC30*(AD30+AE30) -> 400 | AG30: 50 | AH30: 9 | AJ30: =AG30*(AH30+AI30) -> 450 | AK30: 50 | AL30: 4 | AN30: =AK30*(AL30+AM30) -> 200 | AO30: 50 | AR30: =AO30*(AP30+AQ30) -> 0
A31: 20 | B31: 19 | D31: =A31*(B31+C31) -> 380 | F31: 20 | G31: 17 | I31: =F31*(G31+H31) -> 340 | K31: 20 | L31: 13 | N31: =K31*(L31+M31) -> 260 | P31: 20 | Q31: 15 | S31: =P31*(Q31+R31) -> 300 | U31: 20 | V31: 12 | X31: =U31*(V31+W31) -> 240 | Y31: 20 | Z31: 9 | AB31: =Y31*(Z31+AA31) -> 180 | AC31: 20 | AD31: 21 | AF31: =AC31*(AD31+AE31) -> 420 | AG31: 20 | AH31: 18 | AJ31: =AG31*(AH31+AI31) -> 360 | AK31: 20 | AL31: 15 | AN31: =AK31*(AL31+AM31) -> 300 | AO31: 20 | AR31: =AO31*(AP31+AQ31) -> 0
A32: 10 | B32: 17 | D32: =A32*(B32+C32) -> 170 | F32: 10 | G32: 7 | I32: =F32*(G32+H32) -> 70 | K32: 10 | L32: 5 | N32: =K32*(L32+M32) -> 50 | P32: 10 | Q32: 9 | S32: =P32*(Q32+R32) -> 90 | U32: 10 | V32: 5 | X32: =U32*(V32+W32) -> 50 | Y32: 10 | Z32: 7 | AB32: =Y32*(Z32+AA32) -> 70 | AC32: 10 | AD32: 7 | AF32: =AC32*(AD32+AE32) -> 70 | AG32: 10 | AH32: 4 | AJ32: =AG32*(AH32+AI32) -> 40 | AK32: 10 | AL32: 0 | AN32: =AK32*(AL32+AM32) -> 0 | AO32: 10 | AR32: =AO32*(AP32+AQ32) -> 0
A33: 5 | B33: 13 | D33: =A33*(B33+C33) -> 65 | F33: 5 | G33: 9 | I33: =F33*(G33+H33) -> 45 | K33: 5 | L33: 6 | N33: =K33*(L33+M33) -> 30 | P33: 5 | Q33: 11 | S33: =P33*(Q33+R33) -> 55 | U33: 5 | V33: 6 | X33: =U33*(V33+W33) -> 30 | Y33: 5 | Z33: 9 | AB33: =Y33*(Z33+AA33) -> 45 | AC33: 5 | AD33: 0 | AF33: =AC33*(AD33+AE33) -> 0 | AG33: 5 | AH33: 0 | AJ33: =AG33*(AH33+AI33) -> 0 | AK33: 5 | AL33: 0 | AN33: =AK33*(AL33+AM33) -> 0 | AO33: 5 | AR33: =AO33*(AP33+AQ33) -> 0
A34: 2 | B34: 190 | D34: =A34*(B34+C34) -> 380 | F34: 2 | G34: 162 | I34: =F34*(G34+H34) -> 324 | K34: 2 | L34: 144 | N34: =K34*(L34+M34) -> 288 | P34: 2 | Q34: 123 | S34: =P34*(Q34+R34) -> 246 | U34: 2 | V34: 104 | X34: =U34*(V34+W34) -> 208 | Y34: 2 | Z34: 64 | AB34: =Y34*(Z34+AA34) -> 128 | AC34: 2 | AD34: 60 | AF34: =AC34*(AD34+AE34) -> 120 | AG34: 2 | AH34: 131 | AJ34: =AG34*(AH34+AI34) -> 262 | AK34: 2 | AL34: 100 | AN34: =AK34*(AL34+AM34) -> 200 | AO34: 2 | AR34: =AO34*(AP34+AQ34) -> 0
A35: 1 | B35: 129 | D35: =A35*(B35+C35) -> 129 | F35: 1 | G35: 84 | I35: =F35*(G35+H35) -> 84 | K35: 1 | L35: 65 | N35: =K35*(L35+M35) -> 65 | P35: 1 | Q35: 65 | S35: =P35*(Q35+R35) -> 65 | U35: 1 | V35: 39 | X35: =U35*(V35+W35) -> 39 | Y35: 1 | Z35: 33 | AB35: =Y35*(Z35+AA35) -> 33 | AC35: 1 | AD35: 23 | AF35: =AC35*(AD35+AE35) -> 23 | AG35: 1 | AH35: 16 | AJ35: =AG35*(AH35+AI35) -> 16 | AK35: 1 | AL35: 9 | AN35: =AK35*(AL35+AM35) -> 9 | AO35: 1 | AR35: =AO35*(AP35+AQ35) -> 0
A36: 0.5 | B36: 53 | D36: =A36*(B36+C36) -> 26.5 | F36: 0.5 | G36: 51 | I36: =F36*(G36+H36) -> 25.5 | K36: 0.5 | L36: 51 | N36: =K36*(L36+M36) -> 25.5 | P36: 0.5 | Q36: 49 | S36: =P36*(Q36+R36) -> 24.5 | U36: 0.5 | V36: 45 | X36: =U36*(V36+W36) -> 22.5 | Y36: 0.5 | Z36: 47 | AB36: =Y36*(Z36+AA36) -> 23.5 | AC36: 0.5 | AD36: 48 | AF36: =AC36*(AD36+AE36) -> 24 | AG36: 0.5 | AH36: 49 | AJ36: =AG36*(AH36+AI36) -> 24.5 | AK36: 0.5 | AL36: 49 | AN36: =AK36*(AL36+AM36) -> 24.5 | AO36: 0.5 | AR36: =AO36*(AP36+AQ36) -> 0
A37: 0.2 | B37: 12 | D37: =A37*(B37+C37) -> 2.4 | F37: 0.2 | G37: 12 | I37: =F37*(G37+H37) -> 2.4 | K37: 0.2 | L37: 12 | N37: =K37*(L37+M37) -> 2.4 | P37: 0.2 | Q37: 10 | S37: =P37*(Q37+R37) -> 2 | U37: 0.2 | V37: 11 | X37: =U37*(V37+W37) -> 2.2 | Y37: 0.2 | Z37: 11 | AB37: =Y37*(Z37+AA37) -> 2.2 | AC37: 0.2 | AD37: 11 | AF37: =AC37*(AD37+AE37) -> 2.2 | AG37: 0.2 | AH37: 15 | AJ37: =AG37*(AH37+AI37) -> 3 | AK37: 0.2 | AL37: 15 | AN37: =AK37*(AL37+AM37) -> 3 | AO37: 0.2 | AR37: =AO37*(AP37+AQ37) -> 0
A38: 0.1 | B38: 11 | D38: =A38*(B38+C38) -> 1.1 | F38: 0.1 | G38: 11 | I38: =F38*(G38+H38) -> 1.1 | K38: 0.1 | L38: 11 | N38: =K38*(L38+M38) -> 1.1 | P38: 0.1 | Q38: 11 | S38: =P38*(Q38+R38) -> 1.1 | U38: 0.1 | V38: 11 | X38: =U38*(V38+W38) -> 1.1 | Y38: 0.1 | Z38: 11 | AB38: =Y38*(Z38+AA38) -> 1.1 | AC38: 0.1 | AD38: 11 | AF38: =AC38*(AD38+AE38) -> 1.1 | AG38: 0.1 | AH38: 12 | AJ38: =AG38*(AH38+AI38) -> 1.2 | AK38: 0.1 | AL38: 13 | AN38: =AK38*(AL38+AM38) -> 1.3 | AO38: 0.1 | AR38: =AO38*(AP38+AQ38) -> 0
A39: 0.05 | B39: 0 | D39: =A39*(B39+C39) -> 0 | F39: 0.05 | G39: 0 | I39: =F39*(G39+H39) -> 0 | K39: 0.05 | L39: 0 | N39: =K39*(L39+M39) -> 0 | P39: 0.05 | Q39: 0 | S39: =P39*(Q39+R39) -> 0 | U39: 0.05 | V39: 0 | X39: =U39*(V39+W39) -> 0 | Y39: 0.05 | Z39: 0 | AB39: =Y39*(Z39+AA39) -> 0 | AC39: 0.05 | AD39: 1 | AF39: =AC39*(AD39+AE39) -> 0.05 | AG39: 0.05 | AH39: 1 | AJ39: =AG39*(AH39+AI39) -> 0.05 | AK39: 0.05 | AL39: 0 | AN39: =AK39*(AL39+AM39) -> 0 | AO39: 0.05 | AR39: =AO39*(AP39+AQ39) -> 0
G40: 0 | I40: 0
A41: Total | D41: =SUM(D28:D39) -> 1954 | F41: Total | I41: =SUM(I28:I40) -> 1242 | K41: Total | N41: =SUM(N29:N39) -> 1122 | P41: Total | S41: =SUM(S29:S39) -> 1033.6 | U41: Total | X41: =SUM(X28:X39) -> 942.8 | Y41: Total | AB41: =SUM(AB28:AB39) -> 882.8 | AC41: Total | AF41: =SUM(AF28:AF39) -> 1660.35 | AG41: Total | AJ41: =SUM(AJ28:AJ39) -> 1356.75 | AK41: Total | AN41: =SUM(AN28:AN39) -> 1037.8 | AO41: Total | AR41: =SUM(AR28:AR39) -> 0
A43: Caisse intermédiaire | AC43: 3 bons boissons
A44: Durant journée | F44: Durant journée | K44: Durant journée | AO44: Vole 4 bouteilles de Calvados, 1 plaque à induction (40-50 CHF) et jambon
F46: =32-18 -> 14
...

Sheet Données
B1: Liste des coûts effectifs | E1: Vin chaud
A2: ID | C2: Prix | E2: 1 casserole permet de faire : | G2: =G3*5 -> 65 | H2: verres
B3: Total : | C3: =SUM(C4:C49) -> 4144.95 | E3: 1 casserole contient : | G3: =AVERAGE((14),(12)) -> 13 | H3: L | I3: bouteille vin chaud de 1L permet de faire 1,2 L de vin chaud
A4: n°ecri : | B4: 20 oranges pour Vin Chaud | C4: 0 | I4: Donc | J4: 1.4 | K4: l | L4: permet de faire | M4: 7 | N4: verres
A5: n° ecri : | B5: 50 sachets Thé | C5: 0 | E5: 1 verre est vendu : | G5: 6
A6: n° ecri : | B6: 20 fûts | C6: 0
B8: Aligro : courses | C8: 740
B9: Ecomanif | F9: 45626 | G9: 45627 | H9: 45628 | I9: 45629 | J9: 45630 | K9: 45631 | L9: 45632 | M9: 45633 | N9: 45634 | O9: Total période
B10: Boxer | E10: Qtité de vin (l) | H10: =25*0.95 -> 23.75 | I10: =21*0.95 -> 19.95 | J10: =25*0.95 -> 23.75 | K10: =25*0.95 -> 23.75 | L10: 16 | M10: =50*0.95 -> 47.5 | N10: =20*0.95 -> 19 | O10: =SUM(F10:N10) -> 173.7
B11: Bonvillars | E11: Nb de verres | F11: =F10*$M$4 -> 0 | G11: =G10*$M$4 -> 0 | H11: =H10*$M$4 -> 166.25 | I11: =I10*$M$4 -> 139.65 | J11: =J10*$M$4 -> 166.25 | K11: =K10*$M$4 -> 166.25 | L11: =L10*$M$4 -> 112 | M11: =M10*$M$4 -> 332.5 | N11: =N10*$M$4 -> 133 | O11: =SUM(F11:N11) -> 1215.9
E12: Gain | F12: =F$11*$G$5 -> 0 | G12: =G$11*$G$5 -> 0 | H12: =H$11*$G$5 -> 997.5 | I12: =I$11*$G$5 -> 837.9 | J12: =J$11*$G$5 -> 997.5 | K12: =K$11*$G$5 -> 997.5 | L12: =L$11*$G$5 -> 672 | M12: =M$11*$G$5 -> 1995 | N12: =N$11*$G$5 -> 798 | O12: =SUM(F12:N12) -> 7295.4
E13: Taxe ville | F13: =F11*1 -> 0 | G13: =G11*1 -> 0 | H13: =H11*1 -> 166.25 | I13: =I11*1 -> 139.65 | J13: =J11*1 -> 166.25 | K13: =K11*1 -> 166.25 | L13: =L11*1 -> 112 | M13: =M11*1 -> 332.5 | ... O13: =O11*1 -> 1215.9
E14: Différence | F14: =F12-F13 -> 0 | G14: =G12-G13 -> 0 | H14: =H12-H13 -> 831.25 | I14: =I12-I13 -> 698.25 | J14: =J12-J13 -> 831.25 | K14: =K12-K13 -> 831.25 | L14: =L12-L13 -> 560 | M14: =M12-M13 -> 1662.5 | N14: =N12-N13 -> 665 | O14: =SUM(F14:N14) -> 6079.5
E18: Thé Noël/rhum
E19: 1 casserole permet de faire : | G19: =G20*5 -> 65 | H19: verres
E20: 1 casserole contient : | G20: =AVERAGE((14),(12)) -> 13 | H20: L
B22: Bernycool | C22: 3180.7 | E22: 1 verre est vendu : | H22: chf
B23: cautions grognasses | C23: 42
B24: Lucas : courses | C24: 165.05
B25: Lucie : anis | C25: 17.2
B26: patent alcool | C26: 200.00 CHF | F26: 45254 | G26: 45255 | H26: 45256 | I26: 45257 | J26: 45258 | K26: 45259 | L26: 45260 | M26: 45261 | N26: 45262 | O26: Total période
E27: Casseroles utilisées | F27: =1*0.95 -> 0.95 | G27: =1*0.95 -> 0.95 | H27: =2*0.95 -> 1.9 | I27: =0.5*0.95 -> 0.475 | J27: =0.5*0.95 -> 0.475 | K27: =0.5*0.95 -> 0.475 | L27: =1.5*0.95 -> 1.425 | M27: =0.5*0.95 -> 0.475 | N27: =1.5*0.95 -> 1.425 | O27: =SUM(F27:N27) -> 8.55
E28: Nb de verres | F28: =F27*$G$20/0.2 -> 61.75 | G28: =G27*$G$20/0.2 -> 61.75 | H28: =H27*$G$20/0.2 -> 123.5 | I28: =I27*$G$20/0.2 -> 30.875 | J28: =J27*$G$20/0.2 -> 30.875 | K28: =K27*$G$20/0.2 -> 30.875 | L28: =L27*$G$20/0.2 -> 92.625 | M28: =M27*$G$20/0.2 -> 30.875 | N28: =N27*$G$20/0.2 -> 92.625 | O28: =SUM(F28:N28) -> 555.75
E29: Gain estimé | F29: =F28*$G$22 -> 0 | G29: =G28*$G$22 -> 0 | H29: =H28*$G$22 -> 0 | I29: =I28*$G$22 -> 0 | J29: =J28*$G$22 -> 0 | K29: =K28*$G$22 -> 0 | L29: =L28*$G$22 -> 0 | M29: =M28*$G$22 -> 0 | N29: =N28*$G$22 -> 0 | O29: =SUM(F29:N29) -> 0
E30: Taxe ville | F30: =F$28*1 -> 61.75 | G30: =G$28*1 -> 61.75 | H30: =H$28*1 -> 123.5 | I30: =I$28*1 -> 30.875 | J30: =J$28*1 -> 30.875 | K30: =K$28*1 -> 30.875 | L30: =L$28*1 -> 92.625 | M30: =M$28*1 -> 30.875 | N30: =N$28*1 -> 92.625 | O30: =SUM(F30:N30) -> 555.75
E31: Différence | F31: =F29-F30 -> -61.75 | G31: =G29-G30 -> -61.75 | H31: =H29-H30 -> -123.5 | I31: =I29-I30 -> -30.875 | J31: =J29-J30 -> -30.875 | K31: =K29-K30 -> -30.875 | L31: =L29-L30 -> -92.625 | M31: =M29-M30 -> -30.875 | N31: =N29-N30 -> -92.625 | O31: =SUM(F31:N31) -> -555.75
E34: Calcul gains totaux
F36: 45254 | G36: 45255 | H36: 45256 | I36: 45257 | J36: 45258 | K36: 45259 | L36: 45260 | M36: 45261 | N36: 45262 | O36: Total période
E37: Gain cash | F37: =FDC!D24 -> 564 | G37: =FDC!I24 -> 128 | H37: =FDC!N24 -> 120 | I37: =FDC!S24 -> 71.6 | J37: =FDC!X24 -> -10.8 | K37: =FDC!AB24 -> 60 | L37: =FDC!AF24 -> 657.55 | M37: =FDC!AJ24 -> 314.4 | N37: =FDC!AN24 -> 81.05 | O37: =SUM(F37:N37) -> 1985.8
E38: Gain Twint | F38: =1.97+7.89+217.15+848.09 -> 1075.1 | G38: 1107.4 | H38: =882.37+29.61 -> 911.98 | I38: =237.87+288.2 -> 526.07 | J38: =18.75+252.65+448.12 -> 719.52 | K38: =47.38+800.45 -> 847.83 | L38: =19.74+740.21 -> 759.95 | M38: =92.78+953.43 -> 1046.21 | N38: =1103.45+122.39 -> 1225.84 | O38: =SUM(F38:N38) -> 8219.9
E39: Gain banque | F39: 238.15 | G39: 377.21 | H39: 315.43 | I39: 99.47 | J39: 97.51 | K39: 136.82 | L39: 202.89 | M39: 367.23 | N39: 427.89 | O39: =SUM(F39:N39) -> 2262.6
E40: Totaux | F40: =SUM(F37:F39) -> 1877.25 | G40: =SUM(G37:G39) -> 1612.61 | H40: =SUM(H37:H39) -> 1347.41 | I40: =SUM(I37:I39) -> 697.14 | J40: =SUM(J37:J39) -> 806.23 | K40: =SUM(K37:K39) -> 1044.65 | L40: =SUM(L37:L39) -> 1620.39 | M40: =SUM(M37:M39) -> 1727.84 | ... O40: =SUM(O37:O39) -> 12468.3
E41: Gain sans vin ni thé | F41: =F40-F12-F29 -> 1877.25 | G41: =G40-G12-G29 -> 1612.61 | H41: =H40-H12-H29 -> 349.91 | I41: =I40-I12-I29 -> -140.76 | J41: =J40-J12-J29 -> -191.27 | K41: =K40-K12-K29 -> 47.15 | L41: =L40-L12-L29 -> 948.39 | M41: =M40-M12-M29 -> -267.16 | N41: =N40-N12-N29 -> 936.78 | O41: =SUM(F41:N41) -> 5172.9
E44: n° gains Twint | F44: Twints 1,2,3,4 | G44: Twints 7 | H44: Twints 8,9 | I44: Twints 5,6 | J44: Twints 10,11,12 | K44: Twints 13,14 | L44: Twints 15,16 | M44: Twints 17,18 | N44: Twints 19,20

Sheet Gainsetdépenses
A5: Recettes et coûts de Baleinev
A6: Marché de Noël 2023 du 24.11.23 au 03.12.23
A7: Yverdon-les-bains
A8: Créé par Nicolas Baud
B10: 45254 | C10: 45255 | D10: 45256 | E10: 45257 | F10: 45258 | G10: 45259 | H10: 45260 | I10: 45261 | J10: 45262 | K10: 45263 | L10: Total période
A11: Chiffres d'affaires totaux | B11: ='Données'!F$40 -> 1877.25 | C11: ='Données'!G$40 -> 1612.61 | D11: ='Données'!H$40 -> 1347.41 | E11: ='Données'!I$40 -> 697.14 | F11: ='Données'!J$40 -> 806.23 | G11: ='Données'!K$40 -> 1044.65 | H11: ='Données'!L$40 -> 1620.39 | I11: ='Données'!M$40 -> 1727.84 | J11: ='Données'!N$40 -> 1734.78 | K11: =#REF! -> #REF! | L11: =SUM(B11:K11) -> #REF!
A12: Taxe ville 20% gains autres | B12: =(B11/100*20)-B13-B14 -> 314.45 | C12: =(C11/100*20)-C13-C14 -> 261.522 | D12: =(D11/100*20)-D13-D14 -> -19.518 | E12: =(E11/100*20)-E13-E14 -> -29.572 | F12: =(F11/100*20)-F13-F14 -> -34.754 | G12: =(G11/100*20)-G13-G14 -> 12.93 | H12: =(H11/100*20)-H13-H14 -> 120.078 | I12: =(I11/100*20)-I13-I14 -> -16.432 | ... K12: =(K11/100*20)-K13-K14 -> #REF! | L12: =SUM(B12:K12) -> #REF!
A13: Taxe ville verres de vin chaud | B13: =ROUNDDOWN('Données'!F11,0) -> 0 | C13: =ROUNDDOWN('Données'!G11,0) -> 0 | D13: =ROUNDDOWN('Données'!H11,0) -> 166 | E13: =ROUNDDOWN('Données'!I11,0) -> 139 | F13: =ROUNDDOWN('Données'!J11,0) -> 166 | G13: =ROUNDDOWN('Données'!K11,0) -> 166 | H13: =ROUNDDOWN('Données'!L11,0) -> 112 | I13: =ROUNDDOWN('Données'!M11,0) -> 332 | J13: =ROUNDDOWN('Données'!N11,0) -> 133 | K13: =ROUNDDOWN(#REF!,0) -> #REF! | L13: =SUM(B13:K13) -> #REF!
A14: Taxe ville thé de Noël | B14: =ROUNDDOWN('Données'!F28,0) -> 61 | C14: =ROUNDDOWN('Données'!G28,0) -> 61 | D14: =ROUNDDOWN('Données'!H28,0) -> 123 | E14: =ROUNDDOWN('Données'!I28,0) -> 30 | F14: =ROUNDDOWN('Données'!J28,0) -> 30 | G14: =ROUNDDOWN('Données'!K28,0) -> 30 | H14: =ROUNDDOWN('Données'!L28,0) -> 92 | I14: =ROUNDDOWN('Données'!M28,0) -> 30 | J14: =ROUNDDOWN('Données'!N28,0) -> 92 | K14: =ROUNDDOWN(#REF!,0) -> #REF! | L14: =SUM(B14:K14) -> #REF! | M14: =SUM(L12:L14) -> #REF!
A15: Sous-total | B15: =B11-SUM(B12:B14) -> 1501.8 | C15: =C11-SUM(C12:C14) -> 1290.088 | D15: =D11-SUM(D12:D14) -> 1077.928 | E15: =E11-SUM(E12:E14) -> 557.712 | F15: =F11-SUM(F12:F14) -> 644.984 | G15: =G11-SUM(G12:G14) -> 835.72 | H15: =H11-SUM(H12:H14) -> 1296.312 | I15: =I11-SUM(I12:I14) -> 1382.272 | ... K15: =K11-SUM(K12:K14) -> #REF! | L15: =SUM(B15:K15) -> #REF!
A16: Charges d'exploitation | B16: =('Données'!$C$3)/COUNTA($B$10:$K$10) -> 414.495 | C16: =('Données'!$C$3)/COUNTA($B$10:$K$10) -> 414.495 | D16: =('Données'!$C$3)/COUNTA($B$10:$K$10) -> 414.495 | E16: =('Données'!$C$3)/COUNTA($B$10:$K$10) -> 414.495 | F16: =('Données'!$C$3)/COUNTA($B$10:$K$10) -> 414.495 | G16: =('Données'!$C$3)/COUNTA($B$10:$K$10) -> 414.495 | H16: =('Données'!$C$3)/COUNTA($B$10:$K$10) -> 414.495 | I16: =('Données'!$C$3)/COUNTA($B$10:$K$10) -> 414.495 | ... K16: =('Données'!$C$3)/COUNTA($B$10:$K$10) -> 414.495 | L16: =SUM(B16:K16) -> 4144.95
A17: Bénéfices/pertes | B17: =B15-B16 -> 1087.305 | C17: =C15-C16 -> 875.593 | D17: =D15-D16 -> 663.433 | E17: =E15-E16 -> 143.217 | F17: =F15-F16 -> 230.489 | G17: =G15-G16 -> 421.225 | H17: =H15-H16 -> 881.817 | I17: =I15-I16 -> 967.777 | ... K17: =K15-K16 -> #REF! | L17: =SUM(B17:K17) -> #REF!

Sheet Présentation pour Ville
A5: Recettes et coûts de Baleinev
A6: Marché de Noël 2023 du 24.11.23 au 03.12.23
A7: Yverdon-les-bains
A8: Créé par Nicolas Baud
B10: 45254 | C10: 45255 | D10: 45256 | E10: 45257 | F10: 45258 | G10: 45259 | H10: 45260 | I10: 45261 | J10: 45262 | K10: 45263 | L10: Total période
A11: Chiffres d'affaires totaux | B11: ='Données'!F$40 -> 1877.25 | C11: ='Données'!G$40 -> 1612.61 | D11: ='Données'!H$40 -> 1347.41 | E11: ='Données'!I$40 -> 697.14 | F11: ='Données'!J$40 -> 806.23 | G11: ='Données'!K$40 -> 1044.65 | H11: ='Données'!L$40 -> 1620.39 | I11: ='Données'!M$40 -> 1727.84 | J11: ='Données'!N$40 -> 1734.78 | K11: =#REF! -> #REF! | L11: =SUM(B11:K11) -> #REF!
A12: Taxe ville 20% gains autres produits | B12: =(B11/100*20)-B13-B14 -> 314.45 | C12: =(C11/100*20)-C13-C14 -> 261.522 | D12: =(D11/100*20)-D13-D14 -> -19.518 | E12: =(E11/100*20)-E13-E14 -> -29.572 | F12: =(F11/100*20)-F13-F14 -> -34.754 | G12: =(G11/100*20)-G13-G14 -> 12.93 | H12: =(H11/100*20)-H13-H14 -> 120.078 | I12: =(I11/100*20)-I13-I14 -> -16.432 | ... K12: =(K11/100*20)-K13-K14 -> #REF! | L12: =SUM(B12:K12) -> #REF!
A13: Part vin chaud (1CHF/verre) | B13: =ROUNDDOWN('Données'!F11,0) -> 0 | C13: =ROUNDDOWN('Données'!G11,0) -> 0 | D13: =ROUNDDOWN('Données'!H11,0) -> 166 | E13: =ROUNDDOWN('Données'!I11,0) -> 139 | F13: =ROUNDDOWN('Données'!J11,0) -> 166 | G13: =ROUNDDOWN('Données'!K11,0) -> 166 | H13: =ROUNDDOWN('Données'!L11,0) -> 112 | I13: =ROUNDDOWN('Données'!M11,0) -> 332 | J13: =ROUNDDOWN('Données'!N11,0) -> 133 | K13: =ROUNDDOWN(#REF!,0) -> #REF! | L13: =SUM(B13:K13) -> #REF!
A14: Part thé de Noël (1CHF/verre) | B14: =ROUNDDOWN('Données'!F28,0) -> 61 | C14: =ROUNDDOWN('Données'!G28,0) -> 61 | D14: =ROUNDDOWN('Données'!H28,0) -> 123 | E14: =ROUNDDOWN('Données'!I28,0) -> 30 | F14: =ROUNDDOWN('Données'!J28,0) -> 30 | G14: =ROUNDDOWN('Données'!K28,0) -> 30 | H14: =ROUNDDOWN('Données'!L28,0) -> 92 | I14: =ROUNDDOWN('Données'!M28,0) -> 30 | J14: =ROUNDDOWN('Données'!N28,0) -> 92 | K14: =ROUNDDOWN(#REF!,0) -> #REF! | L14: =SUM(B14:K14) -> #REF!
A15: Totaux taxe ville | B15: =SUM(B12:B14) -> 375.45 | C15: =SUM(C12:C14) -> 322.522 | D15: =SUM(D12:D14) -> 269.482 | E15: =SUM(E12:E14) -> 139.428 | F15: =SUM(F12:F14) -> 161.246 | G15: =SUM(G12:G14) -> 208.93 | H15: =SUM(H12:H14) -> 324.078 | I15: =SUM(I12:I14) -> 345.568 | ... K15: =SUM(K12:K14) -> #REF! | L15: =SUM(B15:K15) -> #REF!
A16: Gains après taxe | B16: =B11-B15 -> 1501.8 | C16: =C11-C15 -> 1290.088 | D16: =D11-D15 -> 1077.928 | E16: =E11-E15 -> 557.712 | F16: =F11-F15 -> 644.984 | G16: =G11-G15 -> 835.72 | H16: =H11-H15 -> 1296.312 | I16: =I11-I15 -> 1382.272 | ... K16: =K11-K15 -> #REF! | L16: =SUM(B16:K16) -> #REF!

Sheet Copie de FDC
A1: Marché de Noël
A2: 30.11.2023 au 08.12.2023
A3: Fonds de caisse et comptage gain par jour
A4: 2 caisses combinées
A5: samedi | B5: 45626 | F5: dimanche | G5: =B5+1 -> 45627 | K5: lundi | L5: =G5+1 -> 45628 | P5: mardi | Q5: =L5+1 -> 45629 | U5: Mercedi | V5: =Q5+1 -> 45630 | Y5: Jeudi | Z5: =V5+1 -> 45631 | AC5: vendredi | AD5: =Z5+1 -> 45632 | AG5: samedi | AH5: =AD5+1 -> 45633 | AK5: dimanche | AL5: =AH5+1 -> 45634 | AO5: Dimanche | AP5: =AL5+1 -> 45635
A6: FDC
A7: Monnaies | B7: NB | C7: ajout | D7: Tot | F7: Monnaies | G7: NB | H7: ajout | I7: Tot | K7: Monnaies | L7: NB | M7: ajout | N7: Tot | P7: Monnaies | Q7: NB | R7: ajout | S7: Tot | U7: Monnaies | V7: NB | W7: ajout | X7: Tot | Y7: Monnaies | Z7: NB | AA7: ajout | AB7: Tot | AC7: Monnaies | AD7: NB | AE7: ajout | AF7: Tot | AG7: Monnaies | AH7: NB | AI7: ajout | AJ7: Tot | AK7: Monnaies | AL7: NB | AM7: ajout | AN7: Tot | AO7: Monnaies | AP7: NB | AQ7: ajout | AR7: Tot
A8: 200
A9: 100 | B9: 2 | D9: =A9*(B9+C9) -> 200 | F9: 100 | G9: 2 | I9: =F9*(G9+H9) -> 200 | K9: 100 | L9: 1 | N9: =K9*(L9+M9) -> 100 | P9: 100 | Q9: 1 | S9: =P9*(Q9+R9) -> 100 | U9: 100 | V9: 1 | X9: =U9*(V9+W9) -> 100 | Y9: 100 | Z9: 3 | AB9: =Y9*(Z9+AA9) -> 300 | AC9: 100 | AD9: 1 | AF9: =AC9*(AD9+AE9) -> 100 | AG9: 100 | AH9: 2 | AJ9: =AG9*(AH9+AI9) -> 200 | AK9: 100 | AL9: 1 | AN9: =AK9*(AL9+AM9) -> 100 | AO9: 100 | AP9: 1 | AR9: =AO9*(AP9+AQ9) -> 100
A10: 50 | B10: 2 | D10: =A10*(B10+C10) -> 100 | F10: 50 | G10: 3 | I10: =F10*(G10+H10) -> 150 | K10: 50 | L10: 2 | N10: =K10*(L10+M10) -> 100 | P10: 50 | Q10: 1 | S10: =P10*(Q10+R10) -> 50 | U10: 50 | V10: 1 | X10: =U10*(V10+W10) -> 50 | Y10: 50 | Z10: 7 | AB10: =Y10*(Z10+AA10) -> 350 | AC10: 50 | AD10: 1 | AF10: =AC10*(AD10+AE10) -> 50 | AG10: 50 | AH10: 6 | AJ10: =AG10*(AH10+AI10) -> 300 | AK10: 50 | AL10: 1 | AN10: =AK10*(AL10+AM10) -> 50 | AO10: 50 | AP10: 1 | AR10: =AO10*(AP10+AQ10) -> 50
A11: 20 | B11: 10 | D11: =A11*(B11+C11) -> 200 | F11: 20 | G11: 10 | I11: =F11*(G11+H11) -> 200 | K11: 20 | L11: 2 | N11: =K11*(L11+M11) -> 40 | P11: 20 | Q11: 2 | S11: =P11*(Q11+R11) -> 40 | U11: 20 | V11: 2 | X11: =U11*(V11+W11) -> 40 | Y11: 20 | Z11: 20 | AB11: =Y11*(Z11+AA11) -> 400 | AC11: 20 | AD11: 2 | AF11: =AC11*(AD11+AE11) -> 40 | AG11: 20 | AH11: 9 | AJ11: =AG11*(AH11+AI11) -> 180 | AK11: 20 | AL11: 4 | AN11: =AK11*(AL11+AM11) -> 80 | AO11: 20 | AP11: 4 | AR11: =AO11*(AP11+AQ11) -> 80
A12: 10 | B12: 10 | D12: =A12*(B12+C12) -> 100 | F12: 10 | G12: 0 | I12: =F12*(G12+H12) -> 0 | K12: 10 | L12: 5 | N12: =K12*(L12+M12) -> 50 | P12: 10 | Q12: 10 | S12: =P12*(Q12+R12) -> 100 | U12: 10 | V12: 6 | X12: =U12*(V12+W12) -> 60 | Y12: 10 | Z12: 0 | AB12: =Y12*(Z12+AA12) -> 0 | AC12: 10 | AD12: 10 | AF12: =AC12*(AD12+AE12) -> 100 | AG12: 10 | AH12: 9 | AJ12: =AG12*(AH12+AI12) -> 90 | AK12: 10 | AL12: 10 | AN12: =AK12*(AL12+AM12) -> 100 | AO12: 10 | AP12: 10 | AR12: =AO12*(AP12+AQ12) -> 100
A13: 5 | B13: 30 | D13: =A13*(B13+C13) -> 150 | F13: 5 | G13: 6 | H13: 25 | I13: =F13*(G13+H13) -> 155 | K13: 5 | L13: 1 | M13: 35 | N13: =K13*(L13+M13) -> 180 | P13: 5 | Q13: 50 | S13: =P13*(Q13+R13) -> 250 | U13: 5 | V13: 54 | X13: =U13*(V13+W13) -> 270 | Y13: 5 | Z13: 20 | AB13: =Y13*(Z13+AA13) -> 100 | AC13: 5 | AD13: 50 | AF13: =AC13*(AD13+AE13) -> 250 | AG13: 5 | AH13: =AD33 -> 17 | AJ13: =AG13*(AH13+AI13) -> 85 | AK13: 5 | AL13: 75 | AN13: =AK13*(AL13+AM13) -> 375 | AO13: 5 | AP13: 75 | AR13: =AO13*(AP13+AQ13) -> 375
A14: 2 | B14: 150 | D14: =A14*(B14+C14) -> 300 | F14: 2 | G14: 52 | H14: =140+150 -> 290 | I14: =F14*(G14+H14) -> 684 | K14: 2 | L14: 6 | M14: 90 | N14: =K14*(L14+M14) -> 192 | P14: 2 | Q14: 200 | S14: =P14*(Q14+R14) -> 400 | U14: 2 | V14: 158 | X14: =U14*(V14+W14) -> 316 | Y14: 2 | Z14: 76 | AB14: =Y14*(Z14+AA14) -> 152 | AC14: 2 | AD14: 250 | AE14: 100 | AF14: =AC14*(AD14+AE14) -> 700 | AG14: 2 | AH14: =AD34 -> 145 | AJ14: =AG14*(AH14+AI14) -> 290 | AK14: 2 | AL14: 500 | AN14: =AK14*(AL14+AM14) -> 1000 | AO14: 2 | AP14: 500 | AR14: =AO14*(AP14+AQ14) -> 1000
A15: 1 | B15: 100 | D15: =A15*(B15+C15) -> 100 | F15: 1 | G15: 94 | I15: =F15*(G15+H15) -> 94 | K15: 1 | L15: 4 | M15: 50 | N15: =K15*(L15+M15) -> 54 | P15: 1 | Q15: 100 | S15: =P15*(Q15+R15) -> 100 | U15: 1 | V15: 95 | X15: =U15*(V15+W15) -> 95 | Y15: 1 | Z15: 86 | AB15: =Y15*(Z15+AA15) -> 86 | AC15: 1 | AD15: 100 | AF15: =AC15*(AD15+AE15) -> 100 | AG15: 1 | AH15: =AD35 -> 44 | AI15: 50 | AJ15: =AG15*(AH15+AI15) -> 94 | AK15: 1 | AL15: 300 | AN15: =AK15*(AL15+AM15) -> 300 | AO15: 1 | AP15: 300 | AR15: =AO15*(AP15+AQ15) -> 300
A16: 0.5 | B16: 10 | D16: =A16*(B16+C16) -> 5 | F16: 0.5 | G16: 0 | I16: =F16*(G16+H16) -> 0 | K16: 0.5 | L16: 2 | M16: 400 | N16: =K16*(L16+M16) -> 201 | P16: 0.5 | Q16: 56 | S16: =P16*(Q16+R16) -> 28 | U16: 0.5 | V16: 58 | X16: =U16*(V16+W16) -> 29 | Y16: 0.5 | Z16: 60 | AB16: =Y16*(Z16+AA16) -> 30 | AC16: 0.5 | AD16: 0 | AF16: =AC16*(AD16+AE16) -> 0 | AG16: 0.5 | AH16: =AD36 -> 10 | AJ16: =AG16*(AH16+AI16) -> 5 | AK16: 0.5 | AL16: 0 | AN16: =AK16*(AL16+AM16) -> 0 | AO16: 0.5 | AP16: 0 | AR16: =AO16*(AP16+AQ16) -> 0
A17: 0.2 | D17: =A17*(B17+C17) -> 0 | F17: 0.2 | G17: 0 | I17: =F17*(G17+H17) -> 0 | K17: 0.2 | L17: 0 | N17: =K17*(L17+M17) -> 0 | P17: 0.2 | Q17: 5 | S17: =P17*(Q17+R17) -> 1 | U17: 0.2 | V17: 12 | X17: =U17*(V17+W17) -> 2.4 | Y17: 0.2 | Z17: 12 | AB17: =Y17*(Z17+AA17) -> 2.4 | AC17: 0.2 | AD17: 0 | AF17: =AC17*(AD17+AE17) -> 0 | AG17: 0.2 | AH17: =AD37 -> 5 | AJ17: =AG17*(AH17+AI17) -> 1 | AK17: 0.2 | AL17: 0 | AN17: =AK17*(AL17+AM17) -> 0 | AO17: 0.2 | AP17: 0 | AR17: =AO17*(AP17+AQ17) -> 0
A18: 0.1 | D18: =A18*(B18+C18) -> 0 | F18: 0.1 | G18: 0 | I18: =F18*(G18+H18) -> 0 | K18: 0.1 | L18: 0 | N18: =K18*(L18+M18) -> 0 | P18: 0.1 | Q18: 2 | S18: =P18*(Q18+R18) -> 0.2 | U18: 0.1 | V18: 7 | X18: =U18*(V18+W18) -> 0.7 | Y18: 0.1 | Z18: 7 | AB18: =Y18*(Z18+AA18) -> 0.7 | AC18: 0.1 | AD18: 0 | AF18: =AC18*(AD18+AE18) -> 0 | AG18: 0.1 | AH18: =AD38 -> 0 | AJ18: =AG18*(AH18+AI18) -> 0 | AK18: 0.1 | AL18: 0 | AN18: =AK18*(AL18+AM18) -> 0 | AO18: 0.1 | AP18: 0 | AR18: =AO18*(AP18+AQ18) -> 0
A19: 0.05 | D19: =A19*(B19+C19) -> 0 | F19: 0.05 | G19: 0 | I19: =F19*(G19+H19) -> 0 | K19: 0.05 | L19: 0 | N19: =K19*(L19+M19) -> 0 | P19: 0.05 | Q19: 2 | S19: =P19*(Q19+R19) -> 0.1 | U19: 0.05 | V19: 2 | X19: =U19*(V19+W19) -> 0.1 | Y19: 0.05 | Z19: 2 | AB19: =Y19*(Z19+AA19) -> 0.1 | AC19: 0.05 | AD19: 0 | AF19: =AC19*(AD19+AE19) -> 0 | AG19: 0.05 | AH19: =AD39 -> 0 | AJ19: =AG19*(AH19+AI19) -> 0 | AK19: 0.05 | AL19: 0 | AN19: =AK19*(AL19+AM19) -> 0 | AO19: 0.05 | AP19: 0 | AR19: =AO19*(AP19+AQ19) -> 0
A21: Total fdc | D21: =SUM(D8:D19) -> 1155 | F21: Total fdc | I21: =SUM(I9:I19) -> 1483 | K21: Total fdc | N21: =SUM(N9:N19) -> 917 | P21: Total fdc | S21: =SUM(S9:S19) -> 1069.3 | U21: Total fdc | X21: =SUM(X9:X19) -> 963.2 | Y21: Total fdc | AB21: =SUM(AB9:AB19) -> 1421.2 | AC21: Total fdc | AF21: =SUM(AF9:AF19) -> 1340 | AG21: Total fdc | AJ21: =SUM(AJ9:AJ19) -> 1245 | AK21: Total fdc | AN21: =SUM(AN9:AN19) -> 2005 | AO21: Total fdc | AR21: =SUM(AR9:AR19) -> 2005
A24: Gains | D24: =D41-D21 -> 879.8 | F24: Gains | I24: =I41-I21 -> 1342.3 | K24: Gains | N24: =N41-N21 -> 732.3 | P24: Gains | S24: =S41-S21 -> 173.9 | U24: Gains | X24: =X41-X21 -> 458 | Y24: Gains | AB24: =AB41-AB21 -> 531.05 | AC24: Gains | AF24: =AF41-AF21 -> 575 | AG24: Gains | AJ24: =AJ41-AJ21 -> 635.05 | AK24: Gains | AN24: =AN41-AN21 -> 1366.3 | AO24: Gains | AR24: =AR41-AR21 -> 1083
A26: Comptages clôture de chaque jours de ventes
A27: Monnaies | B27: NB | C27: ajout | D27: Tot | F27: Monnaies | G27: NB | H27: ajout | I27: Tot | K27: Monnaies | L27: NB | M27: ajout | N27: Tot | P27: Monnaies | Q27: NB | R27: ajout | S27: Tot | U27: Monnaies | V27: NB | W27: ajout | X27: Tot | Y27: Monnaies | Z27: NB | AA27: ajout | AB27: Tot | AC27: Monnaies | AD27: NB | AE27: ajout | AF27: Tot | AG27: Monnaies | AH27: NB | AI27: ajout | AJ27: Tot | AK27: Monnaies | AL27: NB | AM27: ajout | AN27: Tot | AO27: Monnaies | AP27: NB | AQ27: ajout | AR27: Tot
A28: 200 | B28: 1 | D28: =A28*(B28+C28) -> 200 | AC28: 200 | AD28: 1 | AF28: =AC28*(AD28+AE28) -> 200 | AG28: 200 | AH28: 3 | AJ28: =AG28*(AH28+AI28) -> 600 | AK28: 200 | AL28: 1 | AN28: =AK28*(AL28+AM28) -> 200 | AO28: 200 | AP28: 1 | AR28: =AO28*(AP28+AQ28) -> 200
A29: 100 | B29: 5 | D29: =A29*(B29+C29) -> 500 | F29: 100 | G29: 8 | I29: =F29*(G29+H29) -> 800 | K29: 100 | L29: 3 | N29: =K29*(L29+M29) -> 300 | P29: 100 | Q29: 3 | S29: =P29*(Q29+R29) -> 300 | U29: 100 | V29: 3 | X29: =U29*(V29+W29) -> 300 | Y29: 100 | Z29: 5 | AB29: =Y29*(Z29+AA29) -> 500 | AC29: 100 | AD29: 4 | AF29: =AC29*(AD29+AE29) -> 400 | AG29: 100 | AH29: 3 | AJ29: =AG29*(AH29+AI29) -> 300 | AK29: 100 | AL29: 4 | AN29: =AK29*(AL29+AM29) -> 400 | AO29: 100 | AP29: 5 | AR29: =AO29*(AP29+AQ29) -> 500
A30: 50 | B30: 8 | D30: =A30*(B30+C30) -> 400 | F30: 50 | G30: 14 | I30: =F30*(G30+H30) -> 700 | K30: 50 | L30: 15 | N30: =K30*(L30+M30) -> 750 | P30: 50 | Q30: 1 | S30: =P30*(Q30+R30) -> 50 | U30: 50 | V30: 7 | X30: =U30*(V30+W30) -> 350 | Y30: 50 | Z30: 11 | AB30: =Y30*(Z30+AA30) -> 550 | AC30: 50 | AD30: 10 | AF30: =AC30*(AD30+AE30) -> 500 | AG30: 50 | AH30: 5 | AJ30: =AG30*(AH30+AI30) -> 250 | AK30: 50 | AL30: 21 | AN30: =AK30*(AL30+AM30) -> 1050 | AO30: 50 | AP30: 7 | AR30: =AO30*(AP30+AQ30) -> 350
A31: 20 | B31: 35 | D31: =A31*(B31+C31) -> 700 | F31: 20 | G31: 61 | I31: =F31*(G31+H31) -> 1220 | K31: 20 | L31: 27 | N31: =K31*(L31+M31) -> 540 | P31: 20 | Q31: 4 | S31: =P31*(Q31+R31) -> 80 | U31: 20 | V31: 20 | X31: =U31*(V31+W31) -> 400 | Y31: 20 | Z31: 33 | AB31: =Y31*(Z31+AA31) -> 660 | AC31: 20 | AD31: 14 | AF31: =AC31*(AD31+AE31) -> 280 | AG31: 20 | AH31: 24 | AJ31: =AG31*(AH31+AI31) -> 480 | AK31: 20 | AL31: 36 | AN31: =AK31*(AL31+AM31) -> 720 | AO31: 20 | AP31: 51 | AR31: =AO31*(AP31+AQ31) -> 1020
A32: 10 | B32: 0 | D32: =A32*(B32+C32) -> 0 | F32: 10 | G32: 9 | I32: =F32*(G32+H32) -> 90 | K32: 10 | L32: 3 | N32: =K32*(L32+M32) -> 30 | P32: 10 | Q32: 10 | S32: =P32*(Q32+R32) -> 100 | U32: 10 | V32: 0 | X32: =U32*(V32+W32) -> 0 | Y32: 10 | Z32: 11 | AB32: =Y32*(Z32+AA32) -> 110 | AC32: 10 | AD32: 11 | AF32: =AC32*(AD32+AE32) -> 110 | AG32: 10 | AH32: 13 | AJ32: =AG32*(AH32+AI32) -> 130 | AK32: 10 | AL32: 12 | AN32: =AK32*(AL32+AM32) -> 120 | AO32: 10 | AP32: 4 | AR32: =AO32*(AP32+AQ32) -> 40
A33: 5 | B33: 6 | D33: =A33*(B33+C33) -> 30 | F33: 5 | G33: 1 | I33: =F33*(G33+H33) -> 5 | K33: 5 | L33: 0 | N33: =K33*(L33+M33) -> 0 | P33: 5 | Q33: 54 | S33: =P33*(Q33+R33) -> 270 | U33: 5 | V33: 20 | X33: =U33*(V33+W33) -> 100 | Y33: 5 | Z33: 11 | AB33: =Y33*(Z33+AA33) -> 55 | AC33: 5 | AD33: 17 | AF33: =AC33*(AD33+AE33) -> 85 | AG33: 5 | AH33: 1 | AJ33: =AG33*(AH33+AI33) -> 5 | AK33: 5 | AL33: 26 | AN33: =AK33*(AL33+AM33) -> 130 | AO33: 5 | AP33: 29 | AR33: =AO33*(AP33+AQ33) -> 145
A34: 2 | B34: 52 | D34: =A34*(B34+C34) -> 104 | F34: 2 | G34: 1 | I34: =F34*(G34+H34) -> 2 | K34: 2 | L34: 0 | N34: =K34*(L34+M34) -> 0 | P34: 2 | Q34: 158 | S34: =P34*(Q34+R34) -> 316 | U34: 2 | V34: 76 | X34: =U34*(V34+W34) -> 152 | Y34: 2 | Z34: 1 | AB34: =Y34*(Z34+AA34) -> 2 | AC34: 2 | AD34: 145 | AF34: =AC34*(AD34+AE34) -> 290 | AG34: 2 | AH34: 31 | AJ34: =AG34*(AH34+AI34) -> 62 | AK34: 2 | AL34: 257 | AN34: =AK34*(AL34+AM34) -> 514 | AO34: 2 | AP34: 272 | AR34: =AO34*(AP34+AQ34) -> 544
A35: 1 | B35: 94 | D35: =A35*(B35+C35) -> 94 | F35: 1 | G35: 4 | I35: =F35*(G35+H35) -> 4 | K35: 1 | L35: 0 | N35: =K35*(L35+M35) -> 0 | P35: 1 | Q35: 95 | S35: =P35*(Q35+R35) -> 95 | U35: 1 | V35: 86 | X35: =U35*(V35+W35) -> 86 | Y35: 1 | Z35: 41 | AB35: =Y35*(Z35+AA35) -> 41 | AC35: 1 | AD35: 44 | AF35: =AC35*(AD35+AE35) -> 44 | AG35: 1 | AH35: 43 | AJ35: =AG35*(AH35+AI35) -> 43 | AK35: 1 | AL35: 230 | AN35: =AK35*(AL35+AM35) -> 230 | AO35: 1 | AP35: 285 | AR35: =AO35*(AP35+AQ35) -> 285
A36: 0.5 | B36: 6 | D36: =A36*(B36+C36) -> 3 | F36: 0.5 | G36: 2 | I36: =F36*(G36+H36) -> 1 | K36: 0.5 | L36: 56 | N36: =K36*(L36+M36) -> 28 | P36: 0.5 | Q36: 58 | S36: =P36*(Q36+R36) -> 29 | U36: 0.5 | V36: 60 | X36: =U36*(V36+W36) -> 30 | Y36: 0.5 | Z36: 62 | AB36: =Y36*(Z36+AA36) -> 31 | AC36: 0.5 | AD36: 10 | AF36: =AC36*(AD36+AE36) -> 5 | AG36: 0.5 | AH36: 17 | AJ36: =AG36*(AH36+AI36) -> 8.5 | AK36: 0.5 | AL36: 11 | AN36: =AK36*(AL36+AM36) -> 5.5 | AO36: 0.5 | AP36: 4 | AR36: =AO36*(AP36+AQ36) -> 2
A37: 0.2 | B37: 9 | D37: =A37*(B37+C37) -> 1.8 | F37: 0.2 | G37: 13 | I37: =F37*(G37+H37) -> 2.6 | K37: 0.2 | L37: 5 | N37: =K37*(L37+M37) -> 1 | P37: 0.2 | Q37: 12 | S37: =P37*(Q37+R37) -> 2.4 | U37: 0.2 | V37: 12 | X37: =U37*(V37+W37) -> 2.4 | Y37: 0.2 | Z37: 12 | AB37: =Y37*(Z37+AA37) -> 2.4 | AC37: 0.2 | AD37: 5 | AF37: =AC37*(AD37+AE37) -> 1 | AG37: 0.2 | AH37: 7 | AJ37: =AG37*(AH37+AI37) -> 1.4 | AK37: 0.2 | AL37: 6 | AN37: =AK37*(AL37+AM37) -> 1.2 | AO37: 0.2 | AP37: 7 | AR37: =AO37*(AP37+AQ37) -> 1.4
A38: 0.1 | B38: 19 | D38: =A38*(B38+C38) -> 1.9 | F38: 0.1 | G38: 7 | I38: =F38*(G38+H38) -> 0.7 | K38: 0.1 | L38: 2 | N38: =K38*(L38+M38) -> 0.2 | P38: 0.1 | Q38: 7 | S38: =P38*(Q38+R38) -> 0.7 | U38: 0.1 | V38: 7 | X38: =U38*(V38+W38) -> 0.7 | Y38: 0.1 | Z38: 7 | AB38: =Y38*(Z38+AA38) -> 0.7 | AC38: 0.1 | AD38: 0 | AF38: =AC38*(AD38+AE38) -> 0 | AG38: 0.1 | AH38: 1 | AJ38: =AG38*(AH38+AI38) -> 0.1 | AK38: 0.1 | AL38: 6 | AN38: =AK38*(AL38+AM38) -> 0.6 | AO38: 0.1 | AP38: 6 | AR38: =AO38*(AP38+AQ38) -> 0.6
A39: 0.05 | B39: 2 | D39: =A39*(B39+C39) -> 0.1 | F39: 0.05 | I39: =F39*(G39+H39) -> 0 | K39: 0.05 | L39: 2 | N39: =K39*(L39+M39) -> 0.1 | P39: 0.05 | Q39: 2 | S39: =P39*(Q39+R39) -> 0.1 | U39: 0.05 | V39: 2 | X39: =U39*(V39+W39) -> 0.1 | Y39: 0.05 | Z39: 3 | AB39: =Y39*(Z39+AA39) -> 0.15 | AC39: 0.05 | AD39: 0 | AF39: =AC39*(AD39+AE39) -> 0 | AG39: 0.05 | AH39: 1 | AJ39: =AG39*(AH39+AI39) -> 0.05 | AK39: 0.05 | AN39: =AK39*(AL39+AM39) -> 0 | AO39: 0.05 | AR39: =AO39*(AP39+AQ39) -> 0
A41: Total | D41: =SUM(D28:D39) -> 2034.8 | F41: Total | I41: =SUM(I29:I39) -> 2825.3 | K41: Total | N41: =SUM(N29:N39) -> 1649.3 | P41: Total | S41: =SUM(S29:S39) -> 1243.2 | U41: Total | X41: =SUM(X29:X39) -> 1421.2 | Y41: Total | AB41: =SUM(AB29:AB39) -> 1952.25 | AC41: Total | AF41: =SUM(AF28:AF39) -> 1915 | AG41: Total | AJ41: =SUM(AJ28:AJ39) -> 1880.05 | AK41: Total | AN41: =SUM(AN28:AN39) -> 3371.3 | AO41: Total | AR41: =SUM(AR28:AR39) -> 3088
A43: Caisse intermédiaire | AC43: 50 euro | AG43: Coffre intermédiaire vidé
A44: Durant journée | F44: Durant journée | K44: Durant journée | P44: Coffre intermédiaire vidé | AG44: Ajout de 125 pièces de 5.- | AO44: Vole 4 bouteilles de Calvados, 1 plaque à induction (40-50 CHF) et jambon
P45: Ajout 33 billets de 10.- | AG45: Ajout de 1250 pièces de 2.-
F46: transformation 14 billets 20.- -> 140x2.- | K46: transformation billet 100.- -> 50x2.- | P46: Ajout 200 pièces de 5.- | AG46: Ajout de 700 pièces de 1.-
...
