Workbook

Sheet JOURNAL
B1: JOURNAL 2025-2026
B2: Bénéfice/Perte | C2: =LOOKUP(9^9,Q:Q)-P4 -> #N/A
B3: Compte | C3: N° | D3: Date | E3: Montant | F3: En faveur de | G3: Libellé | H3: Entré par | I3: Coffre/Banque | J3: Centre de coûts | K3: N°Référence | L3: Solde Compte Courant | M3: Solde Coffre | N3: Solde Compte Epargne | O3: Solde Compte MyPos | P3: Total | V3: Abréviations comptables
C4: 0 | D4: 45866 | G4: solde compte initial | L4: 4619.01 | M4: 1995.65 | N4: 42.64 | O4: =IF(B4="","",IF(I4="CompteMyPos",IF(IF(ISNA(VLOOKUP(B4,DATA!$A$1:$A$15,1,0)),"",VLOOKUP(B4,DATA!$A$1:$A$15,1,0))="",O3+E4,O3-E4),O3)) | P4: =IF(L4="", "", SUM(L4,M4,N4,O4)) -> 6657.3 | V4: MCA | W4: Manuel Cabras
B5: EVENTS / Produits | C5: =C4+1 -> 1 | D5: 45911 | E5: 24 | F5: BLV | G5: Entrée cash journéée d''accueil | H5: MCA | I5: Coffre | J5: JACC | L5: =IF(B5="","",IF(I5="CompteCourant",IF(IF(ISNA(VLOOKUP(B5,DATA!$A$1:$A$16,1,0)),"",VLOOKUP(B5,DATA!$A$1:$A$16,1,0))="",L4+E5,L4-E5),L4)) -> 4619.01 | M5: =IF(B5="","",IF(I5="Coffre",IF(IF(ISNA(VLOOKUP(B5,DATA!$A$1:$A$16,1,0)),"",VLOOKUP(B5,DATA!$A$1:$A$16,1,0))="",M4+E5,M4-E5),M4)) -> 2019.65 | N5: =IF(B5="","",IF(I5="CompteEpargne",IF(IF(ISNA(VLOOKUP(B5,DATA!$A$1:$A$16,1,0)),"",VLOOKUP(B5,DATA!$A$1:$A$16,1,0))="",N4+E5,N4-E5),N4)) -> 42.64 | O5: =IF(B5="","",IF(I5="CompteMyPos",IF(IF(ISNA(VLOOKUP(B5,DATA!$A$1:$A$15,1,0)),"",VLOOKUP(B5,DATA!$A$1:$A$15,1,0))="",O4+E5,O4-E5),O4)) | P5: =IF(L5="", "", SUM(L5,M5,N5,O5)) -> 6681.3
B6: EVENTS / Charges | C6: =C5+1 -> 2 | D6: 45912 | E6: 54 | F6: Landi | G6: JA : Charbon | H6: MCA | I6: CompteCourant | J6: JACC | L6: =IF(B6="","",IF(I6="CompteCourant",IF(IF(ISNA(VLOOKUP(B6,DATA!$A$1:$A$16,1,0)),"",VLOOKUP(B6,DATA!$A$1:$A$16,1,0))="",L5+E6,L5-E6),L5)) -> 4565.01 | M6: =IF(B6="","",IF(I6="Coffre",IF(IF(ISNA(VLOOKUP(B6,DATA!$A$1:$A$16,1,0)),"",VLOOKUP(B6,DATA!$A$1:$A$16,1,0))="",M5+E6,M5-E6),M5)) -> 2019.65 | N6: =IF(B6="","",IF(I6="CompteEpargne",IF(IF(ISNA(VLOOKUP(B6,DATA!$A$1:$A$16,1,0)),"",VLOOKUP(B6,DATA!$A$1:$A$16,1,0))="",N5+E6,N5-E6),N5)) -> 42.64 | O6: =IF(B6="","",IF(I6="CompteMyPos",IF(IF(ISNA(VLOOKUP(B6,DATA!$A$1:$A$15,1,0)),"",VLOOKUP(B6,DATA!$A$1:$A$15,1,0))="",O5+E6,O5-E6),O5)) | P6: =IF(L6="", "", SUM(L6,M6,N6,O6)) -> 6627.3
B7: EVENTS / Charges | C7: =C6+1 -> 3 | D7: 46279 | E7: 175.5 | F7: Landi | G7: SG1 : Charbon | H7: MCA | I7: CompteCourant | J7: SEGRILL1 | L7: =IF(B7="","",IF(I7="CompteCourant",IF(IF(ISNA(VLOOKUP(B7,DATA!$A$1:$A$16,1,0)),"",VLOOKUP(B7,DATA!$A$1:$A$16,1,0))="",L6+E7,L6-E7),L6)) -> 4389.51 | M7: =IF(B7="","",IF(I7="Coffre",IF(IF(ISNA(VLOOKUP(B7,DATA!$A$1:$A$16,1,0)),"",VLOOKUP(B7,DATA!$A$1:$A$16,1,0))="",M6+E7,M6-E7),M6)) -> 2019.65 | N7: =IF(B7="","",IF(I7="CompteEpargne",IF(IF(ISNA(VLOOKUP(B7,DATA!$A$1:$A$16,1,0)),"",VLOOKUP(B7,DATA!$A$1:$A$16,1,0))="",N6+E7,N6-E7),N6)) -> 42.64 | O7: =IF(B7="","",IF(I7="CompteMyPos",IF(IF(ISNA(VLOOKUP(B7,DATA!$A$1:$A$15,1,0)),"",VLOOKUP(B7,DATA!$A$1:$A$15,1,0))="",O6+E7,O6-E7),O6)) | P7: =IF(L7="", "", SUM(L7,M7,N7,O7)) -> 6451.8
B8: DIVERS / Charges | C8: =C7+1 -> 4 | D8: 46279 | E8: 10.8 | F8: Landi | G8: Bière pour local | H8: MCA | I8: CompteCourant | J8: AFTER | L8: =IF(B8="","",IF(I8="CompteCourant",IF(IF(ISNA(VLOOKUP(B8,DATA!$A$1:$A$16,1,0)),"",VLOOKUP(B8,DATA!$A$1:$A$16,1,0))="",L7+E8,L7-E8),L7)) -> 4378.71 | M8: =IF(B8="","",IF(I8="Coffre",IF(IF(ISNA(VLOOKUP(B8,DATA!$A$1:$A$16,1,0)),"",VLOOKUP(B8,DATA!$A$1:$A$16,1,0))="",M7+E8,M7-E8),M7)) -> 2019.65 | N8: =IF(B8="","",IF(I8="CompteEpargne",IF(IF(ISNA(VLOOKUP(B8,DATA!$A$1:$A$16,1,0)),"",VLOOKUP(B8,DATA!$A$1:$A$16,1,0))="",N7+E8,N7-E8),N7)) -> 42.64 | O8: =IF(B8="","",IF(I8="CompteMyPos",IF(IF(ISNA(VLOOKUP(B8,DATA!$A$1:$A$15,1,0)),"",VLOOKUP(B8,DATA!$A$1:$A$15,1,0))="",O7+E8,O7-E8),O7)) | P8: =IF(L8="", "", SUM(L8,M8,N8,O8)) -> 6441
B9: EVENTS / Produits | C9: =C8+1 -> 5 | D9: 45915 | E9: 60 | F9: BLV | G9: SG1 15.09 : Recette lundi midi CASH | H9: MCA | I9: Coffre | J9: SEGRILL1 | L9: =IF(B9="","",IF(I9="CompteCourant",IF(IF(ISNA(VLOOKUP(B9,DATA!$A$1:$A$16,1,0)),"",VLOOKUP(B9,DATA!$A$1:$A$16,1,0))="",L8+E9,L8-E9),L8)) -> 4378.71 | M9: =IF(B9="","",IF(I9="Coffre",IF(IF(ISNA(VLOOKUP(B9,DATA!$A$1:$A$16,1,0)),"",VLOOKUP(B9,DATA!$A$1:$A$16,1,0))="",M8+E9,M8-E9),M8)) -> 2079.65 | N9: =IF(B9="","",IF(I9="CompteEpargne",IF(IF(ISNA(VLOOKUP(B9,DATA!$A$1:$A$16,1,0)),"",VLOOKUP(B9,DATA!$A$1:$A$16,1,0))="",N8+E9,N8-E9),N8)) -> 42.64 | O9: =IF(B9="","",IF(I9="CompteMyPos",IF(IF(ISNA(VLOOKUP(B9,DATA!$A$1:$A$15,1,0)),"",VLOOKUP(B9,DATA!$A$1:$A$15,1,0))="",O8+E9,O8-E9),O8)) | P9: =IF(L9="", "", SUM(L9,M9,N9,O9)) -> 6501
B10: EVENTS / Produits | C10: =C9+1 -> 6 | D10: 45915 | E10: 38 | F10: BLV | G10: SG1 15.09 : Recette lundi après-midi CASH | H10: MCA | I10: Coffre | J10: SEGRILL1 | L10: =IF(B10="","",IF(I10="CompteCourant",IF(IF(ISNA(VLOOKUP(B10,DATA!$A$1:$A$16,1,0)),"",VLOOKUP(B10,DATA!$A$1:$A$16,1,0))="",L9+E10,L9-E10),L9)) -> 4378.71 | M10: =IF(B10="","",IF(I10="Coffre",IF(IF(ISNA(VLOOKUP(B10,DATA!$A$1:$A$16,1,0)),"",VLOOKUP(B10,DATA!$A$1:$A$16,1,0))="",M9+E10,M9-E10),M9)) -> 2117.65 | N10: =IF(B10="","",IF(I10="CompteEpargne",IF(IF(ISNA(VLOOKUP(B10,DATA!$A$1:$A$16,1,0)),"",VLOOKUP(B10,DATA!$A$1:$A$16,1,0))="",N9+E10,N9-E10),N9)) -> 42.64 | O10: =IF(B10="","",IF(I10="CompteMyPos",IF(IF(ISNA(VLOOKUP(B10,DATA!$A$1:$A$15,1,0)),"",VLOOKUP(B10,DATA!$A$1:$A$15,1,0))="",O9+E10,O9-E10),O9)) | P10: =IF(L10="", "", SUM(L10,M10,N10,O10)) -> 6539 | V10: Abréviations libellés
B11: EVENTS / Produits | C11: =C10+1 -> 7 | D11: 45916 | E11: 101.85 | F11: BLV | G11: AL : Entrées au 16.09 (beer money) | H11: MCA | I11: Coffre | J11: AFTER | L11: =IF(B11="","",IF(I11="CompteCourant",IF(IF(ISNA(VLOOKUP(B11,DATA!$A$1:$A$16,1,0)),"",VLOOKUP(B11,DATA!$A$1:$A$16,1,0))="",L10+E11,L10-E11),L10)) -> 4378.71 | M11: =IF(B11="","",IF(I11="Coffre",IF(IF(ISNA(VLOOKUP(B11,DATA!$A$1:$A$16,1,0)),"",VLOOKUP(B11,DATA!$A$1:$A$16,1,0))="",M10+E11,M10-E11),M10)) -> 2219.5 | N11: =IF(B11="","",IF(I11="CompteEpargne",IF(IF(ISNA(VLOOKUP(B11,DATA!$A$1:$A$16,1,0)),"",VLOOKUP(B11,DATA!$A$1:$A$16,1,0))="",N10+E11,N10-E11),N10)) -> 42.64 | O11: =IF(B11="","",IF(I11="CompteMyPos",IF(IF(ISNA(VLOOKUP(B11,DATA!$A$1:$A$15,1,0)),"",VLOOKUP(B11,DATA!$A$1:$A$15,1,0))="",O10+E11,O10-E11),O10)) | P11: =IF(L11="", "", SUM(L11,M11,N11,O11)) -> 6640.85 | V11: AB | W11: After Baleinev
B12: EVENTS / Produits | C12: =C11+1 -> 8 | D12: 45916 | E12: 23 | F12: BLV | G12: SG1 16.09 : Recette CASH | H12: MCA | I12: Coffre | J12: SEGRILL1 | L12: =IF(B12="","",IF(I12="CompteCourant",IF(IF(ISNA(VLOOKUP(B12,DATA!$A$1:$A$16,1,0)),"",VLOOKUP(B12,DATA!$A$1:$A$16,1,0))="",L11+E12,L11-E12),L11)) -> 4378.71 | M12: =IF(B12="","",IF(I12="Coffre",IF(IF(ISNA(VLOOKUP(B12,DATA!$A$1:$A$16,1,0)),"",VLOOKUP(B12,DATA!$A$1:$A$16,1,0))="",M11+E12,M11-E12),M11)) -> 2242.5 | N12: =IF(B12="","",IF(I12="CompteEpargne",IF(IF(ISNA(VLOOKUP(B12,DATA!$A$1:$A$16,1,0)),"",VLOOKUP(B12,DATA!$A$1:$A$16,1,0))="",N11+E12,N11-E12),N11)) -> 42.64 | O12: =IF(B12="","",IF(I12="CompteMyPos",IF(IF(ISNA(VLOOKUP(B12,DATA!$A$1:$A$15,1,0)),"",VLOOKUP(B12,DATA!$A$1:$A$15,1,0))="",O11+E12,O11-E12),O11)) | P12: =IF(L12="", "", SUM(L12,M12,N12,O12)) -> 6663.85 | V12: AGE | W12: Événements AGE
B13: EVENTS / Produits | C13: =C12+1 -> 9 | D13: 45912 | E13: 178.64 | F13: BLV | G13: AL du 10.09 | H13: MCA | I13: CompteCourant | J13: AFTER | L13: =IF(B13="","",IF(I13="CompteCourant",IF(IF(ISNA(VLOOKUP(B13,DATA!$A$1:$A$16,1,0)),"",VLOOKUP(B13,DATA!$A$1:$A$16,1,0))="",L12+E13,L12-E13),L12)) -> 4557.35 | M13: =IF(B13="","",IF(I13="Coffre",IF(IF(ISNA(VLOOKUP(B13,DATA!$A$1:$A$16,1,0)),"",VLOOKUP(B13,DATA!$A$1:$A$16,1,0))="",M12+E13,M12-E13),M12)) -> 2242.5 | N13: =IF(B13="","",IF(I13="CompteEpargne",IF(IF(ISNA(VLOOKUP(B13,DATA!$A$1:$A$16,1,0)),"",VLOOKUP(B13,DATA!$A$1:$A$16,1,0))="",N12+E13,N12-E13),N12)) -> 42.64 | O13: =IF(B13="","",IF(I13="CompteMyPos",IF(IF(ISNA(VLOOKUP(B13,DATA!$A$1:$A$15,1,0)),"",VLOOKUP(B13,DATA!$A$1:$A$15,1,0))="",O12+E13,O12-E13),O12)) | P13: =IF(L13="", "", SUM(L13,M13,N13,O13)) -> 6842.49 | V13: Am | W13: Amalgame
B14: EVENTS / Produits | C14: =C13+1 -> 10 | D14: 45915 | E14: 143.09 | F14: BLV | G14: JA 11.09 : Recette TWINT | H14: MCA | I14: CompteCourant | J14: JACC | L14: =IF(B14="","",IF(I14="CompteCourant",IF(IF(ISNA(VLOOKUP(B14,DATA!$A$1:$A$16,1,0)),"",VLOOKUP(B14,DATA!$A$1:$A$16,1,0))="",L13+E14,L13-E14),L13)) -> 4700.44 | M14: =IF(B14="","",IF(I14="Coffre",IF(IF(ISNA(VLOOKUP(B14,DATA!$A$1:$A$16,1,0)),"",VLOOKUP(B14,DATA!$A$1:$A$16,1,0))="",M13+E14,M13-E14),M13)) -> 2242.5 | N14: =IF(B14="","",IF(I14="CompteEpargne",IF(IF(ISNA(VLOOKUP(B14,DATA!$A$1:$A$16,1,0)),"",VLOOKUP(B14,DATA!$A$1:$A$16,1,0))="",N13+E14,N13-E14),N13)) -> 42.64 | O14: =IF(B14="","",IF(I14="CompteMyPos",IF(IF(ISNA(VLOOKUP(B14,DATA!$A$1:$A$15,1,0)),"",VLOOKUP(B14,DATA!$A$1:$A$15,1,0))="",O13+E14,O13-E14),O13)) | P14: =IF(L14="", "", SUM(L14,M14,N14,O14)) -> 6985.58 | V14: BF22 | W14: Baleinev Festival 2022
B15: EVENTS / Produits | C15: =C14+1 -> 11 | D15: 45917 | E15: 146.03 | F15: BLV | G15: SG1 15.09 : Recette TWINT | H15: MCA | I15: CompteCourant | J15: SEGRILL1 | L15: =IF(B15="","",IF(I15="CompteCourant",IF(IF(ISNA(VLOOKUP(B15,DATA!$A$1:$A$16,1,0)),"",VLOOKUP(B15,DATA!$A$1:$A$16,1,0))="",L14+E15,L14-E15),L14)) -> 4846.47 | M15: =IF(B15="","",IF(I15="Coffre",IF(IF(ISNA(VLOOKUP(B15,DATA!$A$1:$A$16,1,0)),"",VLOOKUP(B15,DATA!$A$1:$A$16,1,0))="",M14+E15,M14-E15),M14)) -> 2242.5 | N15: =IF(B15="","",IF(I15="CompteEpargne",IF(IF(ISNA(VLOOKUP(B15,DATA!$A$1:$A$16,1,0)),"",VLOOKUP(B15,DATA!$A$1:$A$16,1,0))="",N14+E15,N14-E15),N14)) -> 42.64 | O15: =IF(B15="","",IF(I15="CompteMyPos",IF(IF(ISNA(VLOOKUP(B15,DATA!$A$1:$A$15,1,0)),"",VLOOKUP(B15,DATA!$A$1:$A$15,1,0))="",O14+E15,O14-E15),O14)) | P15: =IF(L15="", "", SUM(L15,M15,N15,O15)) -> 7131.61 | V15: BF23 | W15: Baleinev Festival 2023
B16: EVENTS / Produits | C16: =C15+1 -> 12 | D16: 45916 | E16: 153.93 | F16: BLV | G16: SG1 16.09 : Recette TWINT | H16: MCA | I16: CompteCourant | J16: SEGRILL1 | L16: =IF(B16="","",IF(I16="CompteCourant",IF(IF(ISNA(VLOOKUP(B16,DATA!$A$1:$A$16,1,0)),"",VLOOKUP(B16,DATA!$A$1:$A$16,1,0))="",L15+E16,L15-E16),L15)) -> 5000.4 | M16: =IF(B16="","",IF(I16="Coffre",IF(IF(ISNA(VLOOKUP(B16,DATA!$A$1:$A$16,1,0)),"",VLOOKUP(B16,DATA!$A$1:$A$16,1,0))="",M15+E16,M15-E16),M15)) -> 2242.5 | N16: =IF(B16="","",IF(I16="CompteEpargne",IF(IF(ISNA(VLOOKUP(B16,DATA!$A$1:$A$16,1,0)),"",VLOOKUP(B16,DATA!$A$1:$A$16,1,0))="",N15+E16,N15-E16),N15)) -> 42.64 | O16: =IF(B16="","",IF(I16="CompteMyPos",IF(IF(ISNA(VLOOKUP(B16,DATA!$A$1:$A$15,1,0)),"",VLOOKUP(B16,DATA!$A$1:$A$15,1,0))="",O15+E16,O15-E16),O15)) | P16: =IF(L16="", "", SUM(L16,M16,N16,O16)) -> 7285.54 | V16: BS | W16: Baleiski
B17: EVENTS / Produits | C17: =C16+1 -> 13 | D17: 45918 | E17: 236.84 | F17: BLV | G17: SG1 17.09 : Recette TWINT | H17: MCA | I17: CompteCourant | J17: SEGRILL1 | L17: =IF(B17="","",IF(I17="CompteCourant",IF(IF(ISNA(VLOOKUP(B17,DATA!$A$1:$A$16,1,0)),"",VLOOKUP(B17,DATA!$A$1:$A$16,1,0))="",L16+E17,L16-E17),L16)) -> 5237.24 | M17: =IF(B17="","",IF(I17="Coffre",IF(IF(ISNA(VLOOKUP(B17,DATA!$A$1:$A$16,1,0)),"",VLOOKUP(B17,DATA!$A$1:$A$16,1,0))="",M16+E17,M16-E17),M16)) -> 2242.5 | N17: =IF(B17="","",IF(I17="CompteEpargne",IF(IF(ISNA(VLOOKUP(B17,DATA!$A$1:$A$16,1,0)),"",VLOOKUP(B17,DATA!$A$1:$A$16,1,0))="",N16+E17,N16-E17),N16)) -> 42.64 | O17: =IF(B17="","",IF(I17="CompteMyPos",IF(IF(ISNA(VLOOKUP(B17,DATA!$A$1:$A$15,1,0)),"",VLOOKUP(B17,DATA!$A$1:$A$15,1,0))="",O16+E17,O16-E17),O16)) | P17: =IF(L17="", "", SUM(L17,M17,N17,O17)) -> 7522.38 | V17: Div | W17: Divers
B18: EVENTS / Produits | C18: =C17+1 -> 14 | D18: 45919 | E18: 1016.6 | F18: BLV | G18: SG1 18.09 : Recette TWINT | H18: MCA | I18: CompteCourant | J18: SEGRILL1 | L18: =IF(B18="","",IF(I18="CompteCourant",IF(IF(ISNA(VLOOKUP(B18,DATA!$A$1:$A$16,1,0)),"",VLOOKUP(B18,DATA!$A$1:$A$16,1,0))="",L17+E18,L17-E18),L17)) -> 6253.84 | M18: =IF(B18="","",IF(I18="Coffre",IF(IF(ISNA(VLOOKUP(B18,DATA!$A$1:$A$16,1,0)),"",VLOOKUP(B18,DATA!$A$1:$A$16,1,0))="",M17+E18,M17-E18),M17)) -> 2242.5 | N18: =IF(B18="","",IF(I18="CompteEpargne",IF(IF(ISNA(VLOOKUP(B18,DATA!$A$1:$A$16,1,0)),"",VLOOKUP(B18,DATA!$A$1:$A$16,1,0))="",N17+E18,N17-E18),N17)) -> 42.64 | O18: =IF(B18="","",IF(I18="CompteMyPos",IF(IF(ISNA(VLOOKUP(B18,DATA!$A$1:$A$15,1,0)),"",VLOOKUP(B18,DATA!$A$1:$A$15,1,0))="",O17+E18,O17-E18),O17)) | P18: =IF(L18="", "", SUM(L18,M18,N18,O18)) -> 8538.98 | V18: FG | W18: Frais généraux
B19: EVENTS / Produits | C19: =C18+1 -> 15 | D19: 45919 | E19: =646.21+84.87 -> 731.08 | F19: BLV | G19: AL 18.09 : Recette TWINT | H19: MCA | I19: CompteCourant | J19: AFTER | L19: =IF(B19="","",IF(I19="CompteCourant",IF(IF(ISNA(VLOOKUP(B19,DATA!$A$1:$A$16,1,0)),"",VLOOKUP(B19,DATA!$A$1:$A$16,1,0))="",L18+E19,L18-E19),L18)) -> 6984.92 | M19: =IF(B19="","",IF(I19="Coffre",IF(IF(ISNA(VLOOKUP(B19,DATA!$A$1:$A$16,1,0)),"",VLOOKUP(B19,DATA!$A$1:$A$16,1,0))="",M18+E19,M18-E19),M18)) -> 2242.5 | N19: =IF(B19="","",IF(I19="CompteEpargne",IF(IF(ISNA(VLOOKUP(B19,DATA!$A$1:$A$16,1,0)),"",VLOOKUP(B19,DATA!$A$1:$A$16,1,0))="",N18+E19,N18-E19),N18)) -> 42.64 | O19: =IF(B19="","",IF(I19="CompteMyPos",IF(IF(ISNA(VLOOKUP(B19,DATA!$A$1:$A$15,1,0)),"",VLOOKUP(B19,DATA!$A$1:$A$15,1,0))="",O18+E19,O18-E19),O18)) | P19: =IF(L19="", "", SUM(L19,M19,N19,O19)) -> 9270.06 | V19: GM | W19: Grosse murge
B20: EVENTS / Produits | C20: =C19+1 -> 16 | D20: 45920 | E20: 134.48 | F20: BLV | G20: SG 19.09 : Recette TWINT | H20: MCA | I20: CompteCourant | J20: SEGRILL1 | L20: =IF(B20="","",IF(I20="CompteCourant",IF(IF(ISNA(VLOOKUP(B20,DATA!$A$1:$A$16,1,0)),"",VLOOKUP(B20,DATA!$A$1:$A$16,1,0))="",L19+E20,L19-E20),L19)) -> 7119.4 | M20: =IF(B20="","",IF(I20="Coffre",IF(IF(ISNA(VLOOKUP(B20,DATA!$A$1:$A$16,1,0)),"",VLOOKUP(B20,DATA!$A$1:$A$16,1,0))="",M19+#REF!,M19-#REF!),M19)) -> 2242.5 | N20: =IF(B20="","",IF(I20="CompteEpargne",IF(IF(ISNA(VLOOKUP(B20,DATA!$A$1:$A$16,1,0)),"",VLOOKUP(B20,DATA!$A$1:$A$16,1,0))="",N19+#REF!,N19-#REF!),N19)) -> 42.64 | O20: =IF(B20="","",IF(I20="CompteMyPos",IF(IF(ISNA(VLOOKUP(B20,DATA!$A$1:$A$15,1,0)),"",VLOOKUP(B20,DATA!$A$1:$A$15,1,0))="",O19+#REF!,O19-#REF!),O19)) | P20: =IF(L20="", "", SUM(L20,M20,N20,O20)) -> 9404.54 | V20: LB | W20: Local Baleinev
B21: EVENTS / Produits | C21: =C20+1 -> 17 | D21: 45916 | E21: 23 | F21: BLV | G21: SG 16.09 : Recette CASH | H21: MCA | I21: Coffre | J21: SEGRILL1 | L21: =IF(B21="","",IF(I21="CompteCourant",IF(IF(ISNA(VLOOKUP(B21,DATA!$A$1:$A$16,1,0)),"",VLOOKUP(B21,DATA!$A$1:$A$16,1,0))="",L20+E21,L20-E21),L20)) -> 7119.4 | M21: =IF(B21="","",IF(I21="Coffre",IF(IF(ISNA(VLOOKUP(B21,DATA!$A$1:$A$16,1,0)),"",VLOOKUP(B21,DATA!$A$1:$A$16,1,0))="",M20+E20,M20-E20),M20)) -> 2376.98 | N21: =IF(B21="","",IF(I21="CompteEpargne",IF(IF(ISNA(VLOOKUP(B21,DATA!$A$1:$A$16,1,0)),"",VLOOKUP(B21,DATA!$A$1:$A$16,1,0))="",N20+E20,N20-E20),N20)) -> 42.64 | O21: =IF(B21="","",IF(I21="CompteMyPos",IF(IF(ISNA(VLOOKUP(B21,DATA!$A$1:$A$15,1,0)),"",VLOOKUP(B21,DATA!$A$1:$A$15,1,0))="",O20+E20,O20-E20),O20)) | P21: =IF(L21="", "", SUM(L21,M21,N21,O21)) -> 9539.02 | V21: Pa | W21: Passation
B22: EVENTS / Produits | C22: =C21+1 -> 18 | D22: 45918 | E22: 104 | F22: BLV | G22: AL 18.09 : Recette CASH | H22: MCA | I22: Coffre | J22: AFTER | L22: =IF(B22="","",IF(I22="CompteCourant",IF(IF(ISNA(VLOOKUP(B22,DATA!$A$1:$A$16,1,0)),"",VLOOKUP(B22,DATA!$A$1:$A$16,1,0))="",L21+E22,L21-E22),L21)) -> 7119.4 | M22: =IF(B22="","",IF(I22="Coffre",IF(IF(ISNA(VLOOKUP(B22,DATA!$A$1:$A$16,1,0)),"",VLOOKUP(B22,DATA!$A$1:$A$16,1,0))="",M21+E22,M21-E22),M21)) -> 2480.98 | N22: =IF(B22="","",IF(I22="CompteEpargne",IF(IF(ISNA(VLOOKUP(B22,DATA!$A$1:$A$16,1,0)),"",VLOOKUP(B22,DATA!$A$1:$A$16,1,0))="",N21+E22,N21-E22),N21)) -> 42.64 | O22: =IF(B22="","",IF(I22="CompteMyPos",IF(IF(ISNA(VLOOKUP(B22,DATA!$A$1:$A$15,1,0)),"",VLOOKUP(B22,DATA!$A$1:$A$15,1,0))="",O21+E22,O21-E22),O21)) | P22: =IF(L22="", "", SUM(L22,M22,N22,O22)) -> 9643.02 | V22: PO | W22: Portes ouvertes
B23: EVENTS / Produits | C23: =C22+1 -> 19 | D23: 45919 | E23: 3 | F23: BLV | G23: SG 19.09 : Recette CASH | H23: MCA | I23: Coffre | J23: SEGRILL1 | L23: =IF(B23="","",IF(I23="CompteCourant",IF(IF(ISNA(VLOOKUP(B23,DATA!$A$1:$A$16,1,0)),"",VLOOKUP(B23,DATA!$A$1:$A$16,1,0))="",L22+E23,L22-E23),L22)) -> 7119.4 | M23: =IF(B23="","",IF(I23="Coffre",IF(IF(ISNA(VLOOKUP(B23,DATA!$A$1:$A$16,1,0)),"",VLOOKUP(B23,DATA!$A$1:$A$16,1,0))="",M22+E23,M22-E23),M22)) -> 2483.98 | N23: =IF(B23="","",IF(I23="CompteEpargne",IF(IF(ISNA(VLOOKUP(B23,DATA!$A$1:$A$16,1,0)),"",VLOOKUP(B23,DATA!$A$1:$A$16,1,0))="",N22+E23,N22-E23),N22)) -> 42.64 | O23: =IF(B23="","",IF(I23="CompteMyPos",IF(IF(ISNA(VLOOKUP(B23,DATA!$A$1:$A$15,1,0)),"",VLOOKUP(B23,DATA!$A$1:$A$15,1,0))="",O22+E23,O22-E23),O22)) | P23: =IF(L23="", "", SUM(L23,M23,N23,O23)) -> 9646.02 | V23: RI | W23: Raclette Interrassociation
B24: DIVERS / Charges | C24: =C23+1 -> 20 | D24: 45911 | E24: 23.4 | F24: Landi | G24: AG : Achat bières | H24: MCA | I24: CompteCourant | J24: INTERNE | L24: =IF(B24="","",IF(I24="CompteCourant",IF(IF(ISNA(VLOOKUP(B24,DATA!$A$1:$A$16,1,0)),"",VLOOKUP(B24,DATA!$A$1:$A$16,1,0))="",L23+E24,L23-E24),L23)) -> 7096 | M24: =IF(B24="","",IF(I24="Coffre",IF(IF(ISNA(VLOOKUP(B24,DATA!$A$1:$A$16,1,0)),"",VLOOKUP(B24,DATA!$A$1:$A$16,1,0))="",M23+E24,M23-E24),M23)) -> 2483.98 | N24: =IF(B24="","",IF(I24="CompteEpargne",IF(IF(ISNA(VLOOKUP(B24,DATA!$A$1:$A$16,1,0)),"",VLOOKUP(B24,DATA!$A$1:$A$16,1,0))="",N23+E24,N23-E24),N23)) -> 42.64 | P24: =IF(L24="", "", SUM(L24,M24,N24,O24)) -> 9622.62 | V24: ROA | W24: Rock Oz Arène
B25: EVENTS / Charges | C25: =C24+1 -> 21 | D25: 45911 | E25: 10.5 | F25: Denner | G25: JA : Bonbons | H25: MCA | I25: CompteCourant | J25: JACC | L25: =IF(B25="","",IF(I25="CompteCourant",IF(IF(ISNA(VLOOKUP(B25,DATA!$A$1:$A$16,1,0)),"",VLOOKUP(B25,DATA!$A$1:$A$16,1,0))="",L24+E25,L24-E25),L24)) -> 7085.5 | M25: =IF(B25="","",IF(I25="Coffre",IF(IF(ISNA(VLOOKUP(B25,DATA!$A$1:$A$16,1,0)),"",VLOOKUP(B25,DATA!$A$1:$A$16,1,0))="",M24+E25,M24-E25),M24)) -> 2483.98 | N25: =IF(B25="","",IF(I25="CompteEpargne",IF(IF(ISNA(VLOOKUP(B25,DATA!$A$1:$A$16,1,0)),"",VLOOKUP(B25,DATA!$A$1:$A$16,1,0))="",N24+E25,N24-E25),N24)) -> 42.64 | P25: =IF(L25="", "", SUM(L25,M25,N25,O25)) -> 9612.12 | V25: SE | W25: Sans effet
B26: EVENTS / Charges | C26: =C25+1 -> 22 | D26: 45911 | E26: 15 | F26: Landi | G26: JA : Softs | H26: MCA | I26: CompteCourant | J26: JACC | L26: =IF(B26="","",IF(I26="CompteCourant",IF(IF(ISNA(VLOOKUP(B26,DATA!$A$1:$A$16,1,0)),"",VLOOKUP(B26,DATA!$A$1:$A$16,1,0))="",L25+E26,L25-E26),L25)) -> 7070.5 | M26: =IF(B26="","",IF(I26="Coffre",IF(IF(ISNA(VLOOKUP(B26,DATA!$A$1:$A$16,1,0)),"",VLOOKUP(B26,DATA!$A$1:$A$16,1,0))="",M25+E26,M25-E26),M25)) -> 2483.98 | N26: =IF(B26="","",IF(I26="CompteEpargne",IF(IF(ISNA(VLOOKUP(B26,DATA!$A$1:$A$16,1,0)),"",VLOOKUP(B26,DATA!$A$1:$A$16,1,0))="",N25+E26,N25-E26),N25)) -> 42.64 | P26: =IF(L26="", "", SUM(L26,M26,N26,O26)) -> 9597.12 | V26: SG1 | W26: Semaine grillade n°1
B27: SANS EFFET / Produits | C27: =C26+1 -> 23 | D27: 45914 | E27: 334 | F27: BLV | G27: UNILIVE : DEMANDER MAX | H27: MCA | I27: CompteCourant | J27: INTERNE | L27: =IF(B27="","",IF(I27="CompteCourant",IF(IF(ISNA(VLOOKUP(B27,DATA!$A$1:$A$16,1,0)),"",VLOOKUP(B27,DATA!$A$1:$A$16,1,0))="",L26+E27,L26-E27),L26)) -> 7404.5 | M27: =IF(B27="","",IF(I27="Coffre",IF(IF(ISNA(VLOOKUP(B27,DATA!$A$1:$A$16,1,0)),"",VLOOKUP(B27,DATA!$A$1:$A$16,1,0))="",M26+E27,M26-E27),M26)) -> 2483.98 | N27: =IF(B27="","",IF(I27="CompteEpargne",IF(IF(ISNA(VLOOKUP(B27,DATA!$A$1:$A$16,1,0)),"",VLOOKUP(B27,DATA!$A$1:$A$16,1,0))="",N26+E27,N26-E27),N26)) -> 42.64 | P27: =IF(L27="", "", SUM(L27,M27,N27,O27)) -> 9931.12 | V27: SG2 | W27: Semaine grillade n°2
B28: EVENTS / Charges | C28: =C27+1 -> 24 | D28: 45917 | E28: 500 | F28: Commune de Cheseaux | G28: Caution GM | H28: MCA | I28: CompteCourant | J28: GM | L28: =IF(B28="","",IF(I28="CompteCourant",IF(IF(ISNA(VLOOKUP(B28,DATA!$A$1:$A$16,1,0)),"",VLOOKUP(B28,DATA!$A$1:$A$16,1,0))="",L27+E28,L27-E28),L27)) -> 6904.5 | M28: =IF(B28="","",IF(I28="Coffre",IF(IF(ISNA(VLOOKUP(B28,DATA!$A$1:$A$16,1,0)),"",VLOOKUP(B28,DATA!$A$1:$A$16,1,0))="",M27+E28,M27-E28),M27)) -> 2483.98 | N28: =IF(B28="","",IF(I28="CompteEpargne",IF(IF(ISNA(VLOOKUP(B28,DATA!$A$1:$A$16,1,0)),"",VLOOKUP(B28,DATA!$A$1:$A$16,1,0))="",N27+E28,N27-E28),N27)) -> 42.64 | P28: =IF(L28="", "", SUM(L28,M28,N28,O28)) -> 9431.12 | V28: Spo | W28: Sponsoring
B29: EVENTS / Charges | C29: =C28+1 -> 25 | D29: 45918 | E29: 20.5 | F29: Thomas Brêchet | G29: SG1 : Courses Hot Dogs | H29: MCA | I29: Coffre | J29: SEGRILL1 | L29: =IF(B29="","",IF(I29="CompteCourant",IF(IF(ISNA(VLOOKUP(B29,DATA!$A$1:$A$16,1,0)),"",VLOOKUP(B29,DATA!$A$1:$A$16,1,0))="",L28+E29,L28-E29),L28)) -> 6904.5 | M29: =IF(B29="","",IF(I29="Coffre",IF(IF(ISNA(VLOOKUP(B29,DATA!$A$1:$A$16,1,0)),"",VLOOKUP(B29,DATA!$A$1:$A$16,1,0))="",M28+E29,M28-E29),M28)) -> 2463.48 | N29: =IF(B29="","",IF(I29="CompteEpargne",IF(IF(ISNA(VLOOKUP(B29,DATA!$A$1:$A$16,1,0)),"",VLOOKUP(B29,DATA!$A$1:$A$16,1,0))="",N28+E29,N28-E29),N28)) -> 42.64 | O29: =IF(B29="","",IF(J29="CompteEpargne",IF(IF(ISNA(VLOOKUP(B29,DATA!$A$1:$A$16,1,0)),"",VLOOKUP(B29,DATA!$A$1:$A$16,1,0))="",N23+E29,N23-E29),N23)) -> 42.64 | P29: =IF(L29="", "", SUM(L29,M29,N29,O29)) -> 9453.26 | V29: SVC | W29: Semain vin chaud
B30: EVENTS / Charges | C30: =C29+1 -> 26 | D30: 45918 | E30: 47.25 | F30: Thomas Brêchet | G30: SG1 : Courses Hot Dogs | H30: MCA | I30: Coffre | J30: SEGRILL1 | L30: =IF(B30="","",IF(I30="CompteCourant",IF(IF(ISNA(VLOOKUP(B30,DATA!$A$1:$A$16,1,0)),"",VLOOKUP(B30,DATA!$A$1:$A$16,1,0))="",L29+E30,L29-E30),L29)) -> 6904.5 | M30: =IF(B30="","",IF(I30="Coffre",IF(IF(ISNA(VLOOKUP(B30,DATA!$A$1:$A$16,1,0)),"",VLOOKUP(B30,DATA!$A$1:$A$16,1,0))="",M29+E30,M29-E30),M29)) -> 2416.23 | N30: =IF(B30="","",IF(I30="CompteEpargne",IF(IF(ISNA(VLOOKUP(B30,DATA!$A$1:$A$16,1,0)),"",VLOOKUP(B30,DATA!$A$1:$A$16,1,0))="",N29+E30,N29-E30),N29)) -> 42.64 | O30: =IF(B30="","",IF(J30="CompteEpargne",IF(IF(ISNA(VLOOKUP(B30,DATA!$A$1:$A$16,1,0)),"",VLOOKUP(B30,DATA!$A$1:$A$16,1,0))="",O29+E30,O29-E30),O29)) -> 42.64 | P30: =IF(L30="", "", SUM(L30,M30,N30,O30)) -> 9406.01 | V30: SR | W30: stand rentrée
B31: EVENTS / Charges | C31: =C30+1 -> 27 | D31: 45919 | E31: 21.6 | F31: Landi | G31: SG1 : Courses after (softs) | H31: MCA | I31: CompteCourant | J31: SEGRILL1 | L31: =IF(B31="","",IF(I31="CompteCourant",IF(IF(ISNA(VLOOKUP(B31,DATA!$A$1:$A$16,1,0)),"",VLOOKUP(B31,DATA!$A$1:$A$16,1,0))="",L30+E31,L30-E31),L30)) -> 6882.9 | M31: =IF(B31="","",IF(I31="Coffre",IF(IF(ISNA(VLOOKUP(B31,DATA!$A$1:$A$16,1,0)),"",VLOOKUP(B31,DATA!$A$1:$A$16,1,0))="",M30+E31,M30-E31),M30)) -> 2416.23 | N31: =IF(B31="","",IF(I31="CompteEpargne",IF(IF(ISNA(VLOOKUP(B31,DATA!$A$1:$A$16,1,0)),"",VLOOKUP(B31,DATA!$A$1:$A$16,1,0))="",N30+E31,N30-E31),N30)) -> 42.64 | O31: =IF(B31="","",IF(J31="CompteEpargne",IF(IF(ISNA(VLOOKUP(B31,DATA!$A$1:$A$16,1,0)),"",VLOOKUP(B31,DATA!$A$1:$A$16,1,0))="",O30+E31,O30-E31),O30)) -> 42.64 | P31: =IF(L31="", "", SUM(L31,M31,N31,O31)) -> 9384.41 | V31: AL | W31: after local
B32: EVENTS / Produits | C32: =C31+1 -> 28 | D32: 45925 | E32: 700 | F32: BLV | G32: Mobilière : Remboursement incident POS | H32: MCA | I32: CompteCourant | J32: INTERNE | L32: =IF(B32="","",IF(I32="CompteCourant",IF(IF(ISNA(VLOOKUP(B32,DATA!$A$1:$A$16,1,0)),"",VLOOKUP(B32,DATA!$A$1:$A$16,1,0))="",L31+E32,L31-E32),L31)) -> 7582.9 | M32: =IF(B32="","",IF(I32="Coffre",IF(IF(ISNA(VLOOKUP(B32,DATA!$A$1:$A$16,1,0)),"",VLOOKUP(B32,DATA!$A$1:$A$16,1,0))="",M31+E32,M31-E32),M31)) -> 2416.23 | N32: =IF(B32="","",IF(I32="CompteEpargne",IF(IF(ISNA(VLOOKUP(B32,DATA!$A$1:$A$16,1,0)),"",VLOOKUP(B32,DATA!$A$1:$A$16,1,0))="",N31+E32,N31-E32),N31)) -> 42.64 | O32: =IF(B32="","",IF(J32="CompteEpargne",IF(IF(ISNA(VLOOKUP(B32,DATA!$A$1:$A$16,1,0)),"",VLOOKUP(B32,DATA!$A$1:$A$16,1,0))="",O31+E32,O31-E32),O31)) -> 42.64 | P32: =IF(L32="", "", SUM(L32,M32,N32,O32)) -> 10084.41 | V32: AS | W32: apéro de soutien
B33: ADMINISTRATION / Charges | C33: =C32+1 -> 29 | D33: 45930 | E33: 25.2 | F33: BCV | G33: Frais périodiques | H33: MCA | I33: CompteCourant | J33: INTERNE | L33: =IF(B33="","",IF(I33="CompteCourant",IF(IF(ISNA(VLOOKUP(B33,DATA!$A$1:$A$16,1,0)),"",VLOOKUP(B33,DATA!$A$1:$A$16,1,0))="",L32+E33,L32-E33),L32)) -> 7557.7 | M33: =IF(B33="","",IF(I33="Coffre",IF(IF(ISNA(VLOOKUP(B33,DATA!$A$1:$A$16,1,0)),"",VLOOKUP(B33,DATA!$A$1:$A$16,1,0))="",M32+E33,M32-E33),M32)) -> 2416.23 | N33: =IF(B33="","",IF(I33="CompteEpargne",IF(IF(ISNA(VLOOKUP(B33,DATA!$A$1:$A$16,1,0)),"",VLOOKUP(B33,DATA!$A$1:$A$16,1,0))="",N32+E33,N32-E33),N32)) -> 42.64 | O33: =IF(B33="","",IF(J33="CompteEpargne",IF(IF(ISNA(VLOOKUP(B33,DATA!$A$1:$A$16,1,0)),"",VLOOKUP(B33,DATA!$A$1:$A$16,1,0))="",O32+E33,O32-E33),O32)) -> 42.64 | P33: =IF(L33="", "", SUM(L33,M33,N33,O33)) -> 10059.21 | V33: MdN | W33: Marché de Noël
B34: ADMINISTRATION / Charges | C34: =C33+1 -> 30 | D34: 45932 | E34: 120 | F34: Le Csarda | G34: SG : Pizza | H34: MCA | I34: CompteCourant | J34: INTERNE | L34: =IF(B34="","",IF(I34="CompteCourant",IF(IF(ISNA(VLOOKUP(B34,DATA!$A$1:$A$16,1,0)),"",VLOOKUP(B34,DATA!$A$1:$A$16,1,0))="",L33+E34,L33-E34),L33)) -> 7437.7 | M34: =IF(B34="","",IF(I34="Coffre",IF(IF(ISNA(VLOOKUP(B34,DATA!$A$1:$A$16,1,0)),"",VLOOKUP(B34,DATA!$A$1:$A$16,1,0))="",M33+E34,M33-E34),M33)) -> 2416.23 | N34: =IF(B34="","",IF(I34="CompteEpargne",IF(IF(ISNA(VLOOKUP(B34,DATA!$A$1:$A$16,1,0)),"",VLOOKUP(B34,DATA!$A$1:$A$16,1,0))="",N33+E34,N33-E34),N33)) -> 42.64 | O34: =IF(B34="","",IF(J34="CompteEpargne",IF(IF(ISNA(VLOOKUP(B34,DATA!$A$1:$A$16,1,0)),"",VLOOKUP(B34,DATA!$A$1:$A$16,1,0))="",O33+E34,O33-E34),O33)) -> 42.64 | P34: =IF(L34="", "", SUM(L34,M34,N34,O34)) -> 9939.21 | V34: SeM | W34: Semaine de montage
B35: ADMINISTRATION / Produits | C35: =C34+1 -> 31 | D35: 45932 | E35: 156.9 | F35: BLV | G35: SG : Pizzas + boissons | H35: MCA | I35: CompteCourant | J35: INTERNE | L35: =IF(B35="","",IF(I35="CompteCourant",IF(IF(ISNA(VLOOKUP(B35,DATA!$A$1:$A$16,1,0)),"",VLOOKUP(B35,DATA!$A$1:$A$16,1,0))="",L34+E35,L34-E35),L34)) -> 7594.6 | M35: =IF(B35="","",IF(I35="Coffre",IF(IF(ISNA(VLOOKUP(B35,DATA!$A$1:$A$16,1,0)),"",VLOOKUP(B35,DATA!$A$1:$A$16,1,0))="",M34+E35,M34-E35),M34)) -> 2416.23 | N35: =IF(B35="","",IF(I35="CompteEpargne",IF(IF(ISNA(VLOOKUP(B35,DATA!$A$1:$A$16,1,0)),"",VLOOKUP(B35,DATA!$A$1:$A$16,1,0))="",N34+E35,N34-E35),N34)) -> 42.64 | O35: =IF(B35="","",IF(J35="CompteEpargne",IF(IF(ISNA(VLOOKUP(B35,DATA!$A$1:$A$16,1,0)),"",VLOOKUP(B35,DATA!$A$1:$A$16,1,0))="",O34+E35,O34-E35),O34)) -> 42.64 | P35: =IF(L35="", "", SUM(L35,M35,N35,O35)) -> 10096.11 | V35: JA | W35: Journée d'accueil
B36: ADMINISTRATION / Charges | C36: =C35+1 -> 32 | D36: 45957 | E36: 36.75 | F36: Maxime Magnenat | G36: Renouvellement Infomaniak | H36: MCA | I36: CompteCourant | J36: INTERNE | L36: =IF(B36="","",IF(I36="CompteCourant",IF(IF(ISNA(VLOOKUP(B36,DATA!$A$1:$A$16,1,0)),"",VLOOKUP(B36,DATA!$A$1:$A$16,1,0))="",L35+E36,L35-E36),L35)) -> 7557.85 | M36: =IF(B36="","",IF(I36="Coffre",IF(IF(ISNA(VLOOKUP(B36,DATA!$A$1:$A$16,1,0)),"",VLOOKUP(B36,DATA!$A$1:$A$16,1,0))="",M35+E36,M35-E36),M35)) -> 2416.23 | N36: =IF(B36="","",IF(I36="CompteEpargne",IF(IF(ISNA(VLOOKUP(B36,DATA!$A$1:$A$16,1,0)),"",VLOOKUP(B36,DATA!$A$1:$A$16,1,0))="",N35+E36,N35-E36),N35)) -> 42.64 | O36: =IF(B36="","",IF(J36="CompteEpargne",IF(IF(ISNA(VLOOKUP(B36,DATA!$A$1:$A$16,1,0)),"",VLOOKUP(B36,DATA!$A$1:$A$16,1,0))="",O35+E36,O35-E36),O35)) -> 42.64 | P36: =IF(L36="", "", SUM(L36,M36,N36,O36)) -> 10059.36
B37: EVENTS / Charges | C37: =C36+1 -> 33 | D37: 45938 | E37: 47.05 | F37: Thomas Brêchet | G37: DrawOnMe : croques monsieur | H37: MCA | I37: Coffre | J37: EVTCHILL | L37: =IF(B37="","",IF(I37="CompteCourant",IF(IF(ISNA(VLOOKUP(B37,DATA!$A$1:$A$16,1,0)),"",VLOOKUP(B37,DATA!$A$1:$A$16,1,0))="",L36+E37,L36-E37),L36)) -> 7557.85 | M37: =IF(B37="","",IF(I37="Coffre",IF(IF(ISNA(VLOOKUP(B37,DATA!$A$1:$A$16,1,0)),"",VLOOKUP(B37,DATA!$A$1:$A$16,1,0))="",M36+E37,M36-E37),M36)) -> 2369.18 | N37: =IF(B37="","",IF(I37="CompteEpargne",IF(IF(ISNA(VLOOKUP(B37,DATA!$A$1:$A$16,1,0)),"",VLOOKUP(B37,DATA!$A$1:$A$16,1,0))="",N36+E37,N36-E37),N36)) -> 42.64 | O37: =IF(B37="","",IF(J37="CompteEpargne",IF(IF(ISNA(VLOOKUP(B37,DATA!$A$1:$A$16,1,0)),"",VLOOKUP(B37,DATA!$A$1:$A$16,1,0))="",O36+E37,O36-E37),O36)) -> 42.64 | P37: =IF(L37="", "", SUM(L37,M37,N37,O37)) -> 10012.31
B38: EVENTS / Charges | C38: =C37+1 -> 34 | D38: 45933 | E38: 0 | F38: Maxime Magnenat | G38: Courses GM - 26.85 possiblement pas remboursé | H38: MCA | I38: CompteCourant | J38: GM | L38: =IF(B38="","",IF(I38="CompteCourant",IF(IF(ISNA(VLOOKUP(B38,DATA!$A$1:$A$16,1,0)),"",VLOOKUP(B38,DATA!$A$1:$A$16,1,0))="",L37+E38,L37-E38),L37)) -> 7557.85 | M38: =IF(B38="","",IF(I38="Coffre",IF(IF(ISNA(VLOOKUP(B38,DATA!$A$1:$A$16,1,0)),"",VLOOKUP(B38,DATA!$A$1:$A$16,1,0))="",M37+E38,M37-E38),M37)) -> 2369.18 | N38: =IF(B38="","",IF(I38="CompteEpargne",IF(IF(ISNA(VLOOKUP(B38,DATA!$A$1:$A$16,1,0)),"",VLOOKUP(B38,DATA!$A$1:$A$16,1,0))="",N37+E38,N37-E38),N37)) -> 42.64 | O38: =IF(B38="","",IF(J38="CompteEpargne",IF(IF(ISNA(VLOOKUP(B38,DATA!$A$1:$A$16,1,0)),"",VLOOKUP(B38,DATA!$A$1:$A$16,1,0))="",O37+E38,O37-E38),O37)) -> 42.64 | P38: =IF(L38="", "", SUM(L38,M38,N38,O38)) -> 10012.31
B39: ADMINISTRATION / Charges | C39: =C38+1 -> 35 | D39: 45933 | E39: 172.6 | F39: Landi | G39: A COMPLETER | H39: MCA | I39: CompteCourant | L39: =IF(B39="","",IF(I39="CompteCourant",IF(IF(ISNA(VLOOKUP(B39,DATA!$A$1:$A$16,1,0)),"",VLOOKUP(B39,DATA!$A$1:$A$16,1,0))="",L38+E39,L38-E39),L38)) -> 7385.25 | M39: =IF(B39="","",IF(I39="Coffre",IF(IF(ISNA(VLOOKUP(B39,DATA!$A$1:$A$16,1,0)),"",VLOOKUP(B39,DATA!$A$1:$A$16,1,0))="",M38+E39,M38-E39),M38)) -> 2369.18 | N39: =IF(B39="","",IF(I39="CompteEpargne",IF(IF(ISNA(VLOOKUP(B39,DATA!$A$1:$A$16,1,0)),"",VLOOKUP(B39,DATA!$A$1:$A$16,1,0))="",N38+E39,N38-E39),N38)) -> 42.64 | O39: =IF(B39="","",IF(J39="CompteEpargne",IF(IF(ISNA(VLOOKUP(B39,DATA!$A$1:$A$16,1,0)),"",VLOOKUP(B39,DATA!$A$1:$A$16,1,0))="",O38+E39,O38-E39),O38)) -> 42.64 | P39: =IF(L39="", "", SUM(L39,M39,N39,O39)) -> 9839.71
B40: EVENTS / Charges | C40: =C39+1 -> 36 | D40: 45935 | E40: 150 | F40: Laiterie du Chateau | G40: Fromage GM | H40: MCA | I40: CompteCourant | J40: GM | L40: =IF(B40="","",IF(I40="CompteCourant",IF(IF(ISNA(VLOOKUP(B40,DATA!$A$1:$A$16,1,0)),"",VLOOKUP(B40,DATA!$A$1:$A$16,1,0))="",L39+E40,L39-E40),L39)) -> 7235.25 | M40: =IF(B40="","",IF(I40="Coffre",IF(IF(ISNA(VLOOKUP(B40,DATA!$A$1:$A$16,1,0)),"",VLOOKUP(B40,DATA!$A$1:$A$16,1,0))="",M39+E40,M39-E40),M39)) -> 2369.18 | N40: =IF(B40="","",IF(I40="CompteEpargne",IF(IF(ISNA(VLOOKUP(B40,DATA!$A$1:$A$16,1,0)),"",VLOOKUP(B40,DATA!$A$1:$A$16,1,0))="",N39+E40,N39-E40),N39)) -> 42.64 | O40: =IF(B40="","",IF(J40="CompteEpargne",IF(IF(ISNA(VLOOKUP(B40,DATA!$A$1:$A$16,1,0)),"",VLOOKUP(B40,DATA!$A$1:$A$16,1,0))="",O39+E40,O39-E40),O39)) -> 42.64 | P40: =IF(L40="", "", SUM(L40,M40,N40,O40)) -> 9689.71
...

Sheet RESULTATS
B1: RESULTATS
B2: Année | C2: 2025-2026
B3: Version du budget | C3: 1
B4: Date: | C4: =TODAY() -> 46097
C6: Nombre | D6: Prix
B7: Prélocs
B8: Entrées
B9: Billets subventionnés AGE | C9: 300
B11: Départements | C11: BUDGET | I11: Départements | J11: COMPTABILITE
C12: Charges | E12: Produits | G12: Bénéfices/Pertes | J12: Charges | L12: Produits | N12: Bénéfices/Pertes | Q12: Différence | R12: (par rapport au budget)
B13: =SECURITE!A1 -> SECURITE | C13: =SECURITE!E14 -> 11900 | D13: =C13/$C$29 -> 0.10477972 | E13: =SECURITE!E24 -> 0 | F13: =E13/$C$29 -> 0 | G13: =E13-C13 -> -11900 | I13: =B13 -> SECURITE | J13: =SECURITE!E45 -> 0 | K13: =J13/$J$29 -> 0 | L13: =SECURITE!E55 -> 0 | M13: =L13/$L$29 -> 0 | N13: =L13-J13 -> 0 | P13: =I13 -> SECURITE | Q13: =N13-G13 -> 11900
B14: =PROGRAMMATION!A1 -> PROGRAMMATION | C14: =PROGRAMMATION!E20 -> 18000 | D14: =C14/$C$29 -> 0.15849033 | E14: =PROGRAMMATION!E30 -> 0 | F14: =E14/$C$29 -> 0 | G14: =E14-C14 -> -18000 | I14: =B14 -> PROGRAMMATION | J14: =PROGRAMMATION!E75 -> 1415 | K14: =J14/$J$29 -> 0.064807211 | L14: =PROGRAMMATION!E87 -> 0 | M14: =L14/$L$29 -> 0 | N14: =L14-J14 -> -1415 | P14: =I14 -> PROGRAMMATION | Q14: =N14-G14 -> 16585
B15: =TECHNIQUE!A1 -> TECHNIQUE | C15: =TECHNIQUE!E14 -> 20700 | D15: =C15/$C$29 -> 0.18226388 | E15: =TECHNIQUE!E24 -> 0 | F15: =E15/$C$29 -> 0 | G15: =E15-C15 -> -20700 | H15: ? | I15: =B15 -> TECHNIQUE | J15: =TECHNIQUE!E48 -> 0 | K15: =J15/$J$29 -> 0 | L15: =TECHNIQUE!E58 -> 0 | M15: =L15/$L$29 -> 0 | N15: =L15-J15 -> 0 | P15: =I15 -> TECHNIQUE | Q15: =N15-G15 -> 20700
B16: =INFRASTRUCTURE!A1 -> INFRASTRUCTURE | C16: =INFRASTRUCTURE!E20 -> 9990 | D16: =C16/$C$29 -> 0.087962131 | E16: =INFRASTRUCTURE!E29 -> 200 | F16: =E16/$C$29 -> 0.0017610036 | G16: =E16-C16 -> -9790 | I16: =B16 -> INFRASTRUCTURE | J16: =INFRASTRUCTURE!E73 -> 100 | K16: =J16/$J$29 -> 0.0045800149 | L16: =INFRASTRUCTURE!E88 -> 0 | M16: =L16/$L$29 -> 0 | N16: =L16-J16 -> -100 | P16: =I16 -> INFRASTRUCTURE | Q16: =N16-G16 -> 9690
B17: =RAVITAILLEMENT!A1 -> RAVITAILLEMENT | C17: =RAVITAILLEMENT!E13 -> 16750 | D17: =C17/$C$29 -> 0.14748405 | E17: =RAVITAILLEMENT!E22 -> 30400 | F17: =E17/$C$29 -> 0.26767255 | G17: =E17-C17 -> 13650 | I17: =B17 -> RAVITAILLEMENT | J17: =RAVITAILLEMENT!E108 -> 0 | K17: =J17/$J$29 -> 0 | L17: =RAVITAILLEMENT!E144 -> 108 | M17: =L17/$L$29 -> 0.0049464161 | N17: =L17-J17 -> 108 | P17: =I17 -> RAVITAILLEMENT | Q17: =N17-G17 -> -13542
B18: =SPONSORING!A1 -> SPONSORING | C18: =SPONSORING!E11 -> 0 | D18: =C18/$C$29 -> 0 | E18: =SPONSORING!E50 -> 18500 | F18: =E18/$C$29 -> 0.16289284 | G18: =E18-C18 -> 18500 | I18: =B18 -> SPONSORING | J18: =SPONSORING!E71 -> 0 | K18: =J18/$J$29 -> 0 | L18: =SPONSORING!E102 -> 500 | M18: =L18/$L$29 -> 0.022900075 | N18: =L18-J18 -> 500 | P18: =I18 -> SPONSORING | Q18: =N18-G18 -> -18000
B19: =COMMUNICATION!A1 -> COMMUNICATION | C19: =COMMUNICATION!E20 -> 6562 | D19: =C19/$C$29 -> 0.057778529 | E19: =COMMUNICATION!E27 -> 2500 | F19: =E19/$C$29 -> 0.022012545 | G19: =E19-C19 -> -4062 | I19: =B19 -> COMMUNICATION | J19: =COMMUNICATION!E56 -> 0 | K19: =J19/$J$29 -> 0 | L19: =COMMUNICATION!E85 -> 0 | M19: =L19/$L$29 -> 0 | N19: =L19-J19 -> 0 | P19: =I19 -> COMMUNICATION | Q19: =N19-G19 -> 4062
B20: =ADMINISTRATION!A1 -> ADMINISTRATION | C20: =ADMINISTRATION!E15 -> 6020 | D20: =C20/$C$29 -> 0.053006209 | E20: =ADMINISTRATION!E25 -> 800 | F20: =E20/$C$29 -> 0.0070440145 | G20: =E20-C20 -> -5220 | I20: =B20 -> ADMINISTRATION | J20: =ADMINISTRATION!E53 -> 6440.7 | K20: =J20/$J$29 -> 0.29498502 | L20: =ADMINISTRATION!E79 -> 619.29 | M20: =L20/$L$29 -> 0.028363574 | N20: =L20-J20 -> -5821.41 | P20: =I20 -> ADMINISTRATION | Q20: =N20-G20 -> -601.41
B21: =PMW!A1 -> PMW | C21: =PMW!E15 -> 100 | D21: =C21/$C$29 -> 0.00088050182 | E21: =PMW!E25 -> 0 | F21: =E21/$C$29 -> 0 | G21: =E21-C21 -> -100 | I21: =B21 -> PMW | J21: =PMW!E46 -> 0 | K21: =J21/$J$29 -> 0 | L21: =PMW!E56 -> 0 | M21: =L21/$L$29 -> 0 | N21: =L21-J21 -> 0 | P21: =I21 -> PMW | Q21: =N21-G21 -> 100
B22: =DÉCORATION!A1 -> DÉCORATION | C22: =DÉCORATION!E15 -> 500 | D22: =C22/$C$29 -> 0.0044025091 | E22: =DÉCORATION!E25 -> 0 | F22: =E22/$C$29 -> 0 | G22: =E22-C22 -> -500 | I22: =B22 -> DÉCORATION | J22: =DÉCORATION!E46 -> 244.85 | K22: =J22/$J$29 -> 0.011214167 | L22: =DÉCORATION!E56 -> 0 | M22: =L22/$L$29 -> 0 | N22: =L22-J22 -> -244.85 | P22: =I22 -> DÉCORATION | Q22: =N22-G22 -> 255.15
B23: =ÉLECTRICITÉ!A1 -> ÉLECTRICITÉ | C23: =ÉLECTRICITÉ!E15 -> 300 | D23: =C23/$C$29 -> 0.0026415054 | E23: =ÉLECTRICITÉ!E25 -> 0 | F23: =E23/$C$29 -> 0 | G23: =E23-C23 -> -300 | I23: =B23 -> ÉLECTRICITÉ | J23: =ÉLECTRICITÉ!E46 -> 0 | K23: =J23/$J$29 -> 0 | L23: =ÉLECTRICITÉ!E56 -> 0 | M23: =L23/$L$29 -> 0 | N23: =L23-J23 -> 0 | P23: =I23 -> ÉLECTRICITÉ | Q23: =N23-G23 -> 300
B24: =LOGES!A1 -> LOGES | C24: =LOGES!E15 -> 800 | D24: =C24/$C$29 -> 0.0070440145 | E24: =LOGES!E25 -> 0 | F24: =E24/$C$29 -> 0 | G24: =E24-C24 -> -800 | I24: =B24 -> LOGES | J24: =LOGES!E46 -> 0 | K24: =J24/$J$29 -> 0 | L24: =LOGES!E56 -> 0 | M24: =L24/$L$29 -> 0 | N24: =L24-J24 -> 0 | P24: =I24 -> LOGES | Q24: =N24-G24 -> 800
B25: =ENTREES!A1 -> ENTREES | C25: =ENTREES!E12 -> 1770.6 | D25: =C25/$C$29 -> 0.015590165 | E25: =ENTREES!E23 -> 18700 | F25: =E25/$C$29 -> 0.16465384 | G25: =E25-C25 -> 16929.4 | I25: =B25 -> ENTREES | J25: =ENTREES!E35 -> 1117.35 | K25: =J25/$J$29 -> 0.051174797 | L25: =ENTREES!E99 -> 702.75 | M25: =L25/$L$29 -> 0.032186055 | N25: =L25-J25 -> -414.6 | P25: =I25 -> ENTREES | Q25: =N25-G25 -> -17344
B26: =EVENTS!A1 -> EVENTS | C26: =EVENTS!E21 -> 16179 | D26: =C26/$C$29 -> 0.14245639 | E26: =EVENTS!E39 -> 38552 | F26: =E26/$C$29 -> 0.33945106 | G26: =E26-C26 -> 22373 | H26: ? | I26: =B26 -> EVENTS | J26: =EVENTS!E175 -> 9977.29 | K26: =J26/$J$29 -> 0.45696137 | L26: =EVENTS!E450 -> 19903.95 | M26: =L26/$L$29 -> 0.91160388 | N26: =L26-J26 -> 9926.66 | P26: =I26 -> EVENTS | Q26: =N26-G26 -> -12446.34
B27: =DIVERS!A1 -> DIVERS | C27: =DIVERS!E17 -> 4000 | D27: =C27/$C$29 -> 0.035220073 | E27: =DIVERS!E27 -> 0 | F27: =E27/$C$29 -> 0 | G27: =E27-C27 -> -4000 | I27: =B27 -> DIVERS | J27: =DIVERS!E61 -> 34.2 | K27: =J27/$J$29 -> 0.0015663651 | L27: =DIVERS!E92 -> 0 | M27: =L27/$L$29 -> 0 | N27: =L27-J27 -> -34.2 | P27: =I27 -> DIVERS | Q27: =N27-G27 -> 3965.8
B28: BENEFICE/PERTE | C28: =IF(SUM(C13:C27)<SUM(E13:E27),SUM(E13:E27)-SUM(C13:C27),"") | E28: =IF(SUM(E13:E27)>SUM(C13:C27),"",SUM(C13:C27)-SUM(E13:E27)) -> 3919.6 | I28: BENEFICE/PERTE | J28: =IF(SUM(J13:J27)<SUM(L13:L27),SUM(L13:L27)-SUM(J13:J27),"") -> 2504.6 | L28: =IF(SUM(L13:L27)>SUM(J13:J27),"",SUM(J13:J27)-SUM(L13:L27))
B29: TOTAL | C29: =SUM(C13:C28) -> 113571.6 | E29: =SUM(E13:E28) -> 113571.6 | I29: TOTAL | J29: =SUM(J13:J28) -> 21833.99 | L29: =SUM(L13:L28) -> 21833.99 | P29: TOTAL | Q29: =L29-E29 -> -91737.61

Sheet ADMINISTRATION
A1: ADMINISTRATION
A3: BUDGET
A4: Charges | I4: weezevents | J4: PU | K4: Qte | L4: TOT
A5: Mois de facturation | B5: Libellé | E5: Montant | I5: solution bracelet activé | J5: 2.58 | K5: 800 | L5: =K5*J5 -> 2064
B6: Cotisations USLY | E6: 50 | I6: solution si bon prix | J6: 2 | K6: 800 | L6: =K6*J6 -> 1600
B7: Assurance RC | E7: 995 | I7: frais distribution | J7: 0.02 | K7: 30000 | L7: =K7*J7 -> 600
B8: Petzi | E8: 400 | I8: frais remboursement | J8: 100 | K8: 1 | L8: =K8*J8 -> 100
B9: Frais divers | E9: 300 | I9: assistance mail | J9: 0.05 | K9: 800 | L9: =K9*J9 -> 40
B10: POCAMA | E10: 400 | I10: bracelets | J10: 1.1 | K10: 800 | L10: =K10*J10 -> 880
B11: Weezevent (sans frais activation) | E11: 3600 | F11: worst case scenario | I11: transport | J11: 130 | K11: 1 | L11: =K11*J11 -> 130
B12: frais de compte | E12: 150
B13: Bracelets staff | E13: 85
B14: vignette | E14: 40
A15: Total | E15: =SUM(E6:E14) -> 6020
A16: Produits
A17: Mois de facturation | B17: Libellé | E17: Montant
B18: Activation puce (1 CHF 800 festivaliers) | E18: 800
A25: Total | E25: =SUM(E18:E24) -> 800
A27: COMPTABILITE
A28: Charges
A29: N° | B29: Libellé | C29: Date | D29: En faveur de | E29: Montant
A30: =IF(ISNA(VLOOKUP($A$1&" / "&$A$28,JOURNAL!$B$5:$I$1115,2,0)),"",VLOOKUP($A$1&" / "&$A$28,JOURNAL!$B$5:$I$1115,2,0)) -> 29 | B30: =IF($A30="","",VLOOKUP($A30,JOURNAL!$C$5:$I$1115,5,0)) -> Frais périodiques | C30: =IF($A30="","",VLOOKUP($A30,JOURNAL!$C$5:$I$1115,2,0)) -> 45930 | D30: =IF($A30="","",VLOOKUP($A30,JOURNAL!$C$5:$I$1115,4,0)) -> BCV | E30: =IF($A30="","",VLOOKUP($A30,JOURNAL!$C$5:$I$1115,3,0)) -> 25.2
A31: =IF(A30="","",IF(ISNA(VLOOKUP($A$1&" / "&$A$28,INDIRECT(ADDRESS(A30+5,2,1,,"JOURNAL")&":G500"),2,0)),"",VLOOKUP($A$1&" / "&$A$28,INDIRECT(ADDRESS(A30+5,2,1,,"JOURNAL")&":G500"),2,0))) -> 30 | B31: =IF($A31="","",VLOOKUP($A31,JOURNAL!$C$5:$I$1115,5,0)) -> SG : Pizza | C31: =IF($A31="","",VLOOKUP($A31,JOURNAL!$C$5:$I$1115,2,0)) -> 45932 | D31: =IF($A31="","",VLOOKUP($A31,JOURNAL!$C$5:$I$1115,4,0)) -> Le Csarda | E31: =IF($A31="","",VLOOKUP($A31,JOURNAL!$C$5:$I$1115,3,0)) -> 120
A32: =IF(A31="","",IF(ISNA(VLOOKUP($A$1&" / "&$A$28,INDIRECT(ADDRESS(A31+5,2,1,,"JOURNAL")&":G500"),2,0)),"",VLOOKUP($A$1&" / "&$A$28,INDIRECT(ADDRESS(A31+5,2,1,,"JOURNAL")&":G500"),2,0))) -> 32 | B32: =IF($A32="","",VLOOKUP($A32,JOURNAL!$C$5:$I$1115,5,0)) -> Renouvellement Infomaniak | C32: =IF($A32="","",VLOOKUP($A32,JOURNAL!$C$5:$I$1115,2,0)) -> 45957 | D32: =IF($A32="","",VLOOKUP($A32,JOURNAL!$C$5:$I$1115,4,0)) -> Maxime Magnenat | E32: =IF($A32="","",VLOOKUP($A32,JOURNAL!$C$5:$I$1115,3,0)) -> 36.75
A33: =IF(A32="","",IF(ISNA(VLOOKUP($A$1&" / "&$A$28,INDIRECT(ADDRESS(A32+5,2,1,,"JOURNAL")&":G500"),2,0)),"",VLOOKUP($A$1&" / "&$A$28,INDIRECT(ADDRESS(A32+5,2,1,,"JOURNAL")&":G500"),2,0))) -> 35 | B33: =IF($A33="","",VLOOKUP($A33,JOURNAL!$C$5:$I$1115,5,0)) -> A COMPLETER | C33: =IF($A33="","",VLOOKUP($A33,JOURNAL!$C$5:$I$1115,2,0)) -> 45933 | D33: =IF($A33="","",VLOOKUP($A33,JOURNAL!$C$5:$I$1115,4,0)) -> Landi | E33: =IF($A33="","",VLOOKUP($A33,JOURNAL!$C$5:$I$1115,3,0)) -> 172.6
A34: =IF(A33="","",IF(ISNA(VLOOKUP($A$1&" / "&$A$28,INDIRECT(ADDRESS(A33+5,2,1,,"JOURNAL")&":G500"),2,0)),"",VLOOKUP($A$1&" / "&$A$28,INDIRECT(ADDRESS(A33+5,2,1,,"JOURNAL")&":G500"),2,0))) -> 42 | B34: =IF($A34="","",VLOOKUP($A34,JOURNAL!$C$5:$I$1115,5,0)) -> Achat nouvelle cuisine | C34: =IF($A34="","",VLOOKUP($A34,JOURNAL!$C$5:$I$1115,2,0)) -> 45952 | D34: =IF($A34="","",VLOOKUP($A34,JOURNAL!$C$5:$I$1115,4,0)) -> Patrick Magnenat | E34: =IF($A34="","",VLOOKUP($A34,JOURNAL!$C$5:$I$1115,3,0)) -> 2977.65
A35: =IF(A34="","",IF(ISNA(VLOOKUP($A$1&" / "&$A$28,INDIRECT(ADDRESS(A34+5,2,1,,"JOURNAL")&":G500"),2,0)),"",VLOOKUP($A$1&" / "&$A$28,INDIRECT(ADDRESS(A34+5,2,1,,"JOURNAL")&":G500"),2,0))) -> 52 | B35: =IF($A35="","",VLOOKUP($A35,JOURNAL!$C$5:$I$1115,5,0)) -> Correction après comptage caisse | C35: =IF($A35="","",VLOOKUP($A35,JOURNAL!$C$5:$I$1115,2,0)) -> 45925 | D35: =IF($A35="","",VLOOKUP($A35,JOURNAL!$C$5:$I$1115,4,0)) -> BLV | E35: =IF($A35="","",VLOOKUP($A35,JOURNAL!$C$5:$I$1115,3,0)) -> 591.4
A36: =IF(A35="","",IF(ISNA(VLOOKUP($A$1&" / "&$A$28,INDIRECT(ADDRESS(A35+5,2,1,,"JOURNAL")&":G500"),2,0)),"",VLOOKUP($A$1&" / "&$A$28,INDIRECT(ADDRESS(A35+5,2,1,,"JOURNAL")&":G500"),2,0))) -> 54 | B36: =IF($A36="","",VLOOKUP($A36,JOURNAL!$C$5:$I$1115,5,0)) -> note de frais | C36: =IF($A36="","",VLOOKUP($A36,JOURNAL!$C$5:$I$1115,2,0)) -> 45957 | D36: =IF($A36="","",VLOOKUP($A36,JOURNAL!$C$5:$I$1115,4,0)) -> Maxime Magnenat | E36: =IF($A36="","",VLOOKUP($A36,JOURNAL!$C$5:$I$1115,3,0)) -> 26.85
A37: =IF(A36="","",IF(ISNA(VLOOKUP($A$1&" / "&$A$28,INDIRECT(ADDRESS(A36+5,2,1,,"JOURNAL")&":G500"),2,0)),"",VLOOKUP($A$1&" / "&$A$28,INDIRECT(ADDRESS(A36+5,2,1,,"JOURNAL")&":G500"),2,0))) -> 55 | B37: =IF($A37="","",VLOOKUP($A37,JOURNAL!$C$5:$I$1115,5,0)) -> note de frais | C37: =IF($A37="","",VLOOKUP($A37,JOURNAL!$C$5:$I$1115,2,0)) -> 45957 | D37: =IF($A37="","",VLOOKUP($A37,JOURNAL!$C$5:$I$1115,4,0)) -> Manuel Cabras | E37: =IF($A37="","",VLOOKUP($A37,JOURNAL!$C$5:$I$1115,3,0)) -> 210
A38: =IF(A37="","",IF(ISNA(VLOOKUP($A$1&" / "&$A$28,INDIRECT(ADDRESS(A37+5,2,1,,"JOURNAL")&":G700"),2,0)),"",VLOOKUP($A$1&" / "&$A$28,INDIRECT(ADDRESS(A37+5,2,1,,"JOURNAL")&":G700"),2,0))) -> 57 | B38: =IF($A38="","",VLOOKUP($A38,JOURNAL!$C$5:$I$1115,5,0)) -> note de frais | C38: =IF($A38="","",VLOOKUP($A38,JOURNAL!$C$5:$I$1115,2,0)) -> 45961 | D38: =IF($A38="","",VLOOKUP($A38,JOURNAL!$C$5:$I$1115,4,0)) -> Manuel Cabras | E38: =IF($A38="","",VLOOKUP($A38,JOURNAL!$C$5:$I$1115,3,0)) -> 107.6
A39: =IF(A38="","",IF(ISNA(VLOOKUP($A$1&" / "&$A$28,INDIRECT(ADDRESS(A38+5,2,1,,"JOURNAL")&":G700"),2,0)),"",VLOOKUP($A$1&" / "&$A$28,INDIRECT(ADDRESS(A38+5,2,1,,"JOURNAL")&":G700"),2,0))) -> 64 | B39: =IF($A39="","",VLOOKUP($A39,JOURNAL!$C$5:$I$1115,5,0)) -> Dépôt chalet Baleiski | C39: =IF($A39="","",VLOOKUP($A39,JOURNAL!$C$5:$I$1115,2,0)) -> 45972 | D39: =IF($A39="","",VLOOKUP($A39,JOURNAL!$C$5:$I$1115,4,0)) -> Entente intercomm. Crissier | E39: =IF($A39="","",VLOOKUP($A39,JOURNAL!$C$5:$I$1115,3,0)) -> 650
A40: =IF(A39="","",IF(ISNA(VLOOKUP($A$1&" / "&$A$28,INDIRECT(ADDRESS(A39+5,2,1,,"JOURNAL")&":G700"),2,0)),"",VLOOKUP($A$1&" / "&$A$28,INDIRECT(ADDRESS(A39+5,2,1,,"JOURNAL")&":G700"),2,0))) -> 71 | B40: =IF($A40="","",VLOOKUP($A40,JOURNAL!$C$5:$I$1115,5,0)) -> note de frais | C40: =IF($A40="","",VLOOKUP($A40,JOURNAL!$C$5:$I$1115,2,0)) -> 45978 | D40: =IF($A40="","",VLOOKUP($A40,JOURNAL!$C$5:$I$1115,4,0)) -> Gilles Rothermund | E40: =IF($A40="","",VLOOKUP($A40,JOURNAL!$C$5:$I$1115,3,0)) -> 51.5
A41: =IF(A40="","",IF(ISNA(VLOOKUP($A$1&" / "&$A$28,INDIRECT(ADDRESS(A40+5,2,1,,"JOURNAL")&":G700"),2,0)),"",VLOOKUP($A$1&" / "&$A$28,INDIRECT(ADDRESS(A40+5,2,1,,"JOURNAL")&":G700"),2,0))) -> 72 | B41: =IF($A41="","",VLOOKUP($A41,JOURNAL!$C$5:$I$1115,5,0)) -> note de frais | C41: =IF($A41="","",VLOOKUP($A41,JOURNAL!$C$5:$I$1115,2,0)) -> 45978 | D41: =IF($A41="","",VLOOKUP($A41,JOURNAL!$C$5:$I$1115,4,0)) -> Sarah Mallet | E41: =IF($A41="","",VLOOKUP($A41,JOURNAL!$C$5:$I$1115,3,0)) -> 45
A42: =IF(A41="","",IF(ISNA(VLOOKUP($A$1&" / "&$A$28,INDIRECT(ADDRESS(A41+5,2,1,,"JOURNAL")&":G700"),2,0)),"",VLOOKUP($A$1&" / "&$A$28,INDIRECT(ADDRESS(A41+5,2,1,,"JOURNAL")&":G700"),2,0))) -> 76 | B42: =IF($A42="","",VLOOKUP($A42,JOURNAL!$C$5:$I$1115,5,0)) -> 0 | C42: =IF($A42="","",VLOOKUP($A42,JOURNAL!$C$5:$I$1115,2,0)) -> 45982 | D42: =IF($A42="","",VLOOKUP($A42,JOURNAL!$C$5:$I$1115,4,0)) -> PMT CARTE Landi Nord vaudois V | E42: =IF($A42="","",VLOOKUP($A42,JOURNAL!$C$5:$I$1115,3,0)) -> 33.5
A43: =IF(A42="","",IF(ISNA(VLOOKUP($A$1&" / "&$A$28,INDIRECT(ADDRESS(A42+5,2,1,,"JOURNAL")&":G700"),2,0)),"",VLOOKUP($A$1&" / "&$A$28,INDIRECT(ADDRESS(A42+5,2,1,,"JOURNAL")&":G700"),2,0))) -> 78 | B43: =IF($A43="","",VLOOKUP($A43,JOURNAL!$C$5:$I$1115,5,0)) -> 0 | C43: =IF($A43="","",VLOOKUP($A43,JOURNAL!$C$5:$I$1115,2,0)) -> 45983 | D43: =IF($A43="","",VLOOKUP($A43,JOURNAL!$C$5:$I$1115,4,0)) -> PMT CARTE Lidl Yverdon | E43: =IF($A43="","",VLOOKUP($A43,JOURNAL!$C$5:$I$1115,3,0)) -> 46.1
A44: =IF(A43="","",IF(ISNA(VLOOKUP($A$1&" / "&$A$28,INDIRECT(ADDRESS(A43+5,2,1,,"JOURNAL")&":G700"),2,0)),"",VLOOKUP($A$1&" / "&$A$28,INDIRECT(ADDRESS(A43+5,2,1,,"JOURNAL")&":G700"),2,0))) -> 85 | B44: =IF($A44="","",VLOOKUP($A44,JOURNAL!$C$5:$I$1115,5,0)) -> 0 | C44: =IF($A44="","",VLOOKUP($A44,JOURNAL!$C$5:$I$1115,2,0)) -> 45987 | D44: =IF($A44="","",VLOOKUP($A44,JOURNAL!$C$5:$I$1115,4,0)) -> Lucas Charbonnier | E44: =IF($A44="","",VLOOKUP($A44,JOURNAL!$C$5:$I$1115,3,0)) -> 168
A45: =IF(A44="","",IF(ISNA(VLOOKUP($A$1&" / "&$A$28,INDIRECT(ADDRESS(A44+5,2,1,,"JOURNAL")&":G700"),2,0)),"",VLOOKUP($A$1&" / "&$A$28,INDIRECT(ADDRESS(A44+5,2,1,,"JOURNAL")&":G700"),2,0))) -> 86 | B45: =IF($A45="","",VLOOKUP($A45,JOURNAL!$C$5:$I$1115,5,0)) -> ??? | C45: =IF($A45="","",VLOOKUP($A45,JOURNAL!$C$5:$I$1115,2,0)) -> 45987 | D45: =IF($A45="","",VLOOKUP($A45,JOURNAL!$C$5:$I$1115,4,0)) -> Fino Resto SA | E45: =IF($A45="","",VLOOKUP($A45,JOURNAL!$C$5:$I$1115,3,0)) -> 40.2
A46: =IF(A45="","",IF(ISNA(VLOOKUP($A$1&" / "&$A$28,INDIRECT(ADDRESS(A45+5,2,1,,"JOURNAL")&":G700"),2,0)),"",VLOOKUP($A$1&" / "&$A$28,INDIRECT(ADDRESS(A45+5,2,1,,"JOURNAL")&":G700"),2,0))) -> 92 | B46: =IF($A46="","",VLOOKUP($A46,JOURNAL!$C$5:$I$1115,5,0)) -> 0 | C46: =IF($A46="","",VLOOKUP($A46,JOURNAL!$C$5:$I$1115,2,0)) -> 45989 | D46: =IF($A46="","",VLOOKUP($A46,JOURNAL!$C$5:$I$1115,4,0)) -> PMT CARTE Landi Nord vaudois V | E46: =IF($A46="","",VLOOKUP($A46,JOURNAL!$C$5:$I$1115,3,0)) -> 14.05
A47: =IF(A46="","",IF(ISNA(VLOOKUP($A$1&" / "&$A$28,INDIRECT(ADDRESS(A46+5,2,1,,"JOURNAL")&":G700"),2,0)),"",VLOOKUP($A$1&" / "&$A$28,INDIRECT(ADDRESS(A46+5,2,1,,"JOURNAL")&":G700"),2,0))) -> 95 | B47: =IF($A47="","",VLOOKUP($A47,JOURNAL!$C$5:$I$1115,5,0)) -> note de frais | C47: =IF($A47="","",VLOOKUP($A47,JOURNAL!$C$5:$I$1115,2,0)) -> 45992 | D47: =IF($A47="","",VLOOKUP($A47,JOURNAL!$C$5:$I$1115,4,0)) -> Maxime Magnenat | E47: =IF($A47="","",VLOOKUP($A47,JOURNAL!$C$5:$I$1115,3,0)) -> 370
A48: =IF(A47="","",IF(ISNA(VLOOKUP($A$1&" / "&$A$28,INDIRECT(ADDRESS(A47+5,2,1,,"JOURNAL")&":G700"),2,0)),"",VLOOKUP($A$1&" / "&$A$28,INDIRECT(ADDRESS(A47+5,2,1,,"JOURNAL")&":G700"),2,0))) -> 100 | B48: =IF($A48="","",VLOOKUP($A48,JOURNAL!$C$5:$I$1115,5,0)) -> 0 | C48: =IF($A48="","",VLOOKUP($A48,JOURNAL!$C$5:$I$1115,2,0)) -> 45993 | D48: =IF($A48="","",VLOOKUP($A48,JOURNAL!$C$5:$I$1115,4,0)) -> Maxime : PIZZAS SG 3 | E48: =IF($A48="","",VLOOKUP($A48,JOURNAL!$C$5:$I$1115,3,0)) -> 72
...

Sheet COMMUNICATION
A1: COMMUNICATION
A3: BUDGET
A4: Charges
A5: Mois de facturation | B5: Libellé | E5: Montant
A7: Novembre | B7: Stickers Baleinev édition 2026 Online Printers - étiquettes adhésives, ø 5cm, 90g/m² papier blanc structuré, 2000 pièces | E7: 155
A8: Décembre
A9: Fevrier | B9: Affiches festival, A2, impression recto seul, 115g/m² papier affiche (dos bleu), 500 impressions | E9: 145
A10: Fevrier | B10: Flyers festival, A5, impression recto/verso, 250g/m² papier couché, 1'000 impressions | E10: 65
A11: Fevrier | B11: Bâches PVC affichées à l'écoles, 300 x 150 cm, 500g/m² PVC mat, 2 bâches, Options supplémentaires ourlet et oeillets tout autour | E11: 190
A12: Fevrier | B12: Bâches PVC entrée de la ville, 400 x 50 cm, 500g/m² PVC mat, 2 bâches, Options supplémentaires ourlet et oeillets tout autour | E12: 120
A13: Avril | B13: Mise en place des bâches | E13: 400
A14: Fevrier | B14: T-shirts, hoodies, autre vêtement | E14: 3000
A15: Mars | B15: Concours réseaux sociaux 4 billets à gagner | E15: 100
A16: Septembre | B16: Site web | E16: 37
A17: Fevrier | B17: Social Media Marketing (Publicités en ligne) | E17: 2000 | G17: Voir campagne : mieux cibler (- de thune + de renta)
A18: Fevrier | B18: Goodies (Briquets) | E18: 0
A19: Janvier | B19: Pixartprinting bâche Travys/sponsors grande scène (présidence PV Travys) | E19: 350
A20: Total | E20: =SUM(E6:E19) -> 6562
A21: Produits
A22: Mois de facturation | B22: Libellé | E22: Montant
A23: Avril | B23: T-shirts, hoodies, autres vetements | E23: 2500
A27: Total | E27: =SUM(E23:E26) -> 2500
A29: COMPTABILITE
A30: Charges
A31: N° | B31: Libellé | C31: Date | D31: En faveur de | E31: Montant
A32: =IF(ISNA(VLOOKUP($A$1&" / "&$A$30,JOURNAL!$B$5:$I$1115,2,0)),"",VLOOKUP($A$1&" / "&$A$30,JOURNAL!$B$5:$I$277,2,0)) | B32: =IF($A32="","",VLOOKUP($A32,JOURNAL!$C$5:$I$1115,5,0)) | C32: =IF($A32="","",VLOOKUP($A32,JOURNAL!$C$5:$I$1115,2,0)) | D32: =IF($A32="","",VLOOKUP($A32,JOURNAL!$C$5:$I$1115,4,0)) | E32: =IF($A32="","",VLOOKUP($A32,JOURNAL!$C$5:$I$1115,3,0))
A33: =IF(A32="","",IF(ISNA(VLOOKUP($A$1&" / "&$A$30,INDIRECT(ADDRESS(A32+5,2,1,,"JOURNAL")&":G500"),2,0)),"",VLOOKUP($A$1&" / "&$A$30,INDIRECT(ADDRESS(A32+5,2,1,,"JOURNAL")&":G500"),2,0))) | B33: =IF($A33="","",VLOOKUP($A33,JOURNAL!$C$5:$I$1115,5,0)) | C33: =IF($A33="","",VLOOKUP($A33,JOURNAL!$C$5:$I$1115,2,0)) | D33: =IF($A33="","",VLOOKUP($A33,JOURNAL!$C$5:$I$1115,4,0)) | E33: =IF($A33="","",VLOOKUP($A33,JOURNAL!$C$5:$I$1115,3,0))
A34: =IF(A33="","",IF(ISNA(VLOOKUP($A$1&" / "&$A$30,INDIRECT(ADDRESS(A33+5,2,1,,"JOURNAL")&":G500"),2,0)),"",VLOOKUP($A$1&" / "&$A$30,INDIRECT(ADDRESS(A33+5,2,1,,"JOURNAL")&":G500"),2,0))) | B34: =IF($A34="","",VLOOKUP($A34,JOURNAL!$C$5:$I$1115,5,0)) | C34: =IF($A34="","",VLOOKUP($A34,JOURNAL!$C$5:$I$1115,2,0)) | D34: =IF($A34="","",VLOOKUP($A34,JOURNAL!$C$5:$I$1115,4,0)) | E34: =IF($A34="","",VLOOKUP($A34,JOURNAL!$C$5:$I$1115,3,0))
A35: =IF(A34="","",IF(ISNA(VLOOKUP($A$1&" / "&$A$30,INDIRECT(ADDRESS(A34+5,2,1,,"JOURNAL")&":G500"),2,0)),"",VLOOKUP($A$1&" / "&$A$30,INDIRECT(ADDRESS(A34+5,2,1,,"JOURNAL")&":G500"),2,0))) | B35: =IF($A35="","",VLOOKUP($A35,JOURNAL!$C$5:$I$1115,5,0)) | C35: =IF($A35="","",VLOOKUP($A35,JOURNAL!$C$5:$I$1115,2,0)) | D35: =IF($A35="","",VLOOKUP($A35,JOURNAL!$C$5:$I$1115,4,0)) | E35: =IF($A35="","",VLOOKUP($A35,JOURNAL!$C$5:$I$1115,3,0))
A36: =IF(A35="","",IF(ISNA(VLOOKUP($A$1&" / "&$A$30,INDIRECT(ADDRESS(A35+5,2,1,,"JOURNAL")&":G500"),2,0)),"",VLOOKUP($A$1&" / "&$A$30,INDIRECT(ADDRESS(A35+5,2,1,,"JOURNAL")&":G500"),2,0))) | B36: =IF($A36="","",VLOOKUP($A36,JOURNAL!$C$5:$I$1115,5,0)) | C36: =IF($A36="","",VLOOKUP($A36,JOURNAL!$C$5:$I$1115,2,0)) | D36: =IF($A36="","",VLOOKUP($A36,JOURNAL!$C$5:$I$1115,4,0)) | E36: =IF($A36="","",VLOOKUP($A36,JOURNAL!$C$5:$I$1115,3,0))
A37: =IF(A36="","",IF(ISNA(VLOOKUP($A$1&" / "&$A$30,INDIRECT(ADDRESS(A36+5,2,1,,"JOURNAL")&":G500"),2,0)),"",VLOOKUP($A$1&" / "&$A$30,INDIRECT(ADDRESS(A36+5,2,1,,"JOURNAL")&":G500"),2,0))) | B37: =IF($A37="","",VLOOKUP($A37,JOURNAL!$C$5:$I$1115,5,0)) | C37: =IF($A37="","",VLOOKUP($A37,JOURNAL!$C$5:$I$1115,2,0)) | D37: =IF($A37="","",VLOOKUP($A37,JOURNAL!$C$5:$I$1115,4,0)) | E37: =IF($A37="","",VLOOKUP($A37,JOURNAL!$C$5:$I$1115,3,0))
A38: =IF(A37="","",IF(ISNA(VLOOKUP($A$1&" / "&$A$30,INDIRECT(ADDRESS(A37+5,2,1,,"JOURNAL")&":G500"),2,0)),"",VLOOKUP($A$1&" / "&$A$30,INDIRECT(ADDRESS(A37+5,2,1,,"JOURNAL")&":G500"),2,0))) | B38: =IF($A38="","",VLOOKUP($A38,JOURNAL!$C$5:$I$1115,5,0)) | C38: =IF($A38="","",VLOOKUP($A38,JOURNAL!$C$5:$I$1115,2,0)) | D38: =IF($A38="","",VLOOKUP($A38,JOURNAL!$C$5:$I$1115,4,0)) | E38: =IF($A38="","",VLOOKUP($A38,JOURNAL!$C$5:$I$1115,3,0))
A39: =IF(A38="","",IF(ISNA(VLOOKUP($A$1&" / "&$A$30,INDIRECT(ADDRESS(A38+5,2,1,,"JOURNAL")&":G500"),2,0)),"",VLOOKUP($A$1&" / "&$A$30,INDIRECT(ADDRESS(A38+5,2,1,,"JOURNAL")&":G500"),2,0))) | B39: =IF($A39="","",VLOOKUP($A39,JOURNAL!$C$5:$I$1115,5,0)) | C39: =IF($A39="","",VLOOKUP($A39,JOURNAL!$C$5:$I$1115,2,0)) | D39: =IF($A39="","",VLOOKUP($A39,JOURNAL!$C$5:$I$1115,4,0)) | E39: =IF($A39="","",VLOOKUP($A39,JOURNAL!$C$5:$I$1115,3,0))
A40: =IF(A39="","",IF(ISNA(VLOOKUP($A$1&" / "&$A$30,INDIRECT(ADDRESS(A39+5,2,1,,"JOURNAL")&":G500"),2,0)),"",VLOOKUP($A$1&" / "&$A$30,INDIRECT(ADDRESS(A39+5,2,1,,"JOURNAL")&":G500"),2,0))) | B40: =IF($A40="","",VLOOKUP($A40,JOURNAL!$C$5:$I$1115,5,0)) | C40: =IF($A40="","",VLOOKUP($A40,JOURNAL!$C$5:$I$1115,2,0)) | D40: =IF($A40="","",VLOOKUP($A40,JOURNAL!$C$5:$I$1115,4,0)) | E40: =IF($A40="","",VLOOKUP($A40,JOURNAL!$C$5:$I$1115,3,0))
A41: =IF(A40="","",IF(ISNA(VLOOKUP($A$1&" / "&$A$30,INDIRECT(ADDRESS(A40+5,2,1,,"JOURNAL")&":G700"),2,0)),"",VLOOKUP($A$1&" / "&$A$30,INDIRECT(ADDRESS(A40+5,2,1,,"JOURNAL")&":G700"),2,0))) | B41: =IF($A41="","",VLOOKUP($A41,JOURNAL!$C$5:$I$1115,5,0)) | C41: =IF($A41="","",VLOOKUP($A41,JOURNAL!$C$5:$I$1115,2,0)) | D41: =IF($A41="","",VLOOKUP($A41,JOURNAL!$C$5:$I$1115,4,0)) | E41: =IF($A41="","",VLOOKUP($A41,JOURNAL!$C$5:$I$1115,3,0))
A42: =IF(A41="","",IF(ISNA(VLOOKUP($A$1&" / "&$A$30,INDIRECT(ADDRESS(A41+5,2,1,,"JOURNAL")&":G700"),2,0)),"",VLOOKUP($A$1&" / "&$A$30,INDIRECT(ADDRESS(A41+5,2,1,,"JOURNAL")&":G700"),2,0))) | B42: =IF($A42="","",VLOOKUP($A42,JOURNAL!$C$5:$I$1115,5,0)) | C42: =IF($A42="","",VLOOKUP($A42,JOURNAL!$C$5:$I$1115,2,0)) | D42: =IF($A42="","",VLOOKUP($A42,JOURNAL!$C$5:$I$1115,4,0)) | E42: =IF($A42="","",VLOOKUP($A42,JOURNAL!$C$5:$I$1115,3,0))
A43: =IF(A42="","",IF(ISNA(VLOOKUP($A$1&" / "&$A$30,INDIRECT(ADDRESS(A42+5,2,1,,"JOURNAL")&":G700"),2,0)),"",VLOOKUP($A$1&" / "&$A$30,INDIRECT(ADDRESS(A42+5,2,1,,"JOURNAL")&":G700"),2,0))) | B43: =IF($A43="","",VLOOKUP($A43,JOURNAL!$C$5:$I$1115,5,0)) | C43: =IF($A43="","",VLOOKUP($A43,JOURNAL!$C$5:$I$1115,2,0)) | D43: =IF($A43="","",VLOOKUP($A43,JOURNAL!$C$5:$I$1115,4,0)) | E43: =IF($A43="","",VLOOKUP($A43,JOURNAL!$C$5:$I$1115,3,0))
A44: =IF(A43="","",IF(ISNA(VLOOKUP($A$1&" / "&$A$30,INDIRECT(ADDRESS(A43+5,2,1,,"JOURNAL")&":G700"),2,0)),"",VLOOKUP($A$1&" / "&$A$30,INDIRECT(ADDRESS(A43+5,2,1,,"JOURNAL")&":G700"),2,0))) | B44: =IF($A44="","",VLOOKUP($A44,JOURNAL!$C$5:$I$1115,5,0)) | C44: =IF($A44="","",VLOOKUP($A44,JOURNAL!$C$5:$I$1115,2,0)) | D44: =IF($A44="","",VLOOKUP($A44,JOURNAL!$C$5:$I$1115,4,0)) | E44: =IF($A44="","",VLOOKUP($A44,JOURNAL!$C$5:$I$1115,3,0))
A45: =IF(A44="","",IF(ISNA(VLOOKUP($A$1&" / "&$A$30,INDIRECT(ADDRESS(A44+5,2,1,,"JOURNAL")&":G700"),2,0)),"",VLOOKUP($A$1&" / "&$A$30,INDIRECT(ADDRESS(A44+5,2,1,,"JOURNAL")&":G700"),2,0))) | B45: =IF($A45="","",VLOOKUP($A45,JOURNAL!$C$5:$I$1115,5,0)) | C45: =IF($A45="","",VLOOKUP($A45,JOURNAL!$C$5:$I$1115,2,0)) | D45: =IF($A45="","",VLOOKUP($A45,JOURNAL!$C$5:$I$1115,4,0)) | E45: =IF($A45="","",VLOOKUP($A45,JOURNAL!$C$5:$I$1115,3,0))
A46: =IF(A45="","",IF(ISNA(VLOOKUP($A$1&" / "&$A$30,INDIRECT(ADDRESS(A45+5,2,1,,"JOURNAL")&":G700"),2,0)),"",VLOOKUP($A$1&" / "&$A$30,INDIRECT(ADDRESS(A45+5,2,1,,"JOURNAL")&":G700"),2,0))) | B46: =IF($A46="","",VLOOKUP($A46,JOURNAL!$C$5:$I$1115,5,0)) | C46: =IF($A46="","",VLOOKUP($A46,JOURNAL!$C$5:$I$1115,2,0)) | D46: =IF($A46="","",VLOOKUP($A46,JOURNAL!$C$5:$I$1115,4,0)) | E46: =IF($A46="","",VLOOKUP($A46,JOURNAL!$C$5:$I$1115,3,0))
...

Sheet DÉCORATION
A1: DÉCORATION
A3: BUDGET
A4: Charges
A5: Mois de facturation | B5: Libellé | E5: Montant
B6: Décoration festival | E6: 500 | F6: Contrôle d'accès par Staff | I6: Contrôle entrée par Balelec | K6: A valider lors de la présentation du thème
A15: Total | E15: =SUM(E6:E14) -> 500
A16: Produits
A17: Mois de facturation | B17: Libellé | E17: Montant
A25: Total | E25: =SUM(E18:E24) -> 0
A27: COMPTABILITE
A28: Charges
A29: N° | B29: Libellé | C29: Date | D29: En faveur de | E29: Montant
A30: =IF(ISNA(VLOOKUP($A$1&" / "&$A$28,JOURNAL!$B$5:$I$277,2,0)),"",VLOOKUP($A$1&" / "&$A$28,JOURNAL!$B$5:$I$277,2,0)) -> 70 | B30: =IF($A30="","",VLOOKUP($A30,JOURNAL!$C$5:$I$1115,5,0)) -> note de frais deco | C30: =IF($A30="","",VLOOKUP($A30,JOURNAL!$C$5:$I$1115,2,0)) -> 45978 | D30: =IF($A30="","",VLOOKUP($A30,JOURNAL!$C$5:$I$1115,4,0)) -> Cécile Cabaret | E30: =IF($A30="","",VLOOKUP($A30,JOURNAL!$C$5:$I$1115,3,0)) -> 114.8
A31: =IF(A30="","",IF(ISNA(VLOOKUP($A$1&" / "&$A$28,INDIRECT(ADDRESS(A30+5,2,1,,"JOURNAL")&":G500"),2,0)),"",VLOOKUP($A$1&" / "&$A$28,INDIRECT(ADDRESS(A30+5,2,1,,"JOURNAL")&":G500"),2,0))) -> 188 | B31: =IF($A31="","",VLOOKUP($A31,JOURNAL!$C$5:$I$1115,5,0)) -> Commande affiches | C31: =IF($A31="","",VLOOKUP($A31,JOURNAL!$C$5:$I$1115,2,0)) -> 46084 | D31: =IF($A31="","",VLOOKUP($A31,JOURNAL!$C$5:$I$1115,4,0)) -> Elia Nicolo | E31: =IF($A31="","",VLOOKUP($A31,JOURNAL!$C$5:$I$1115,3,0)) -> 130.05
A32: =IF(A31="","",IF(ISNA(VLOOKUP($A$1&" / "&$A$28,INDIRECT(ADDRESS(A31+5,2,1,,"JOURNAL")&":G500"),2,0)),"",VLOOKUP($A$1&" / "&$A$28,INDIRECT(ADDRESS(A31+5,2,1,,"JOURNAL")&":G500"),2,0))) | B32: =IF($A32="","",VLOOKUP($A32,JOURNAL!$C$5:$I$1115,5,0)) | C32: =IF($A32="","",VLOOKUP($A32,JOURNAL!$C$5:$I$1115,2,0)) | D32: =IF($A32="","",VLOOKUP($A32,JOURNAL!$C$5:$I$1115,4,0)) | E32: =IF($A32="","",VLOOKUP($A32,JOURNAL!$C$5:$I$1115,3,0))
A33: =IF(A32="","",IF(ISNA(VLOOKUP($A$1&" / "&$A$28,INDIRECT(ADDRESS(A32+5,2,1,,"JOURNAL")&":G500"),2,0)),"",VLOOKUP($A$1&" / "&$A$28,INDIRECT(ADDRESS(A32+5,2,1,,"JOURNAL")&":G500"),2,0))) | B33: =IF($A33="","",VLOOKUP($A33,JOURNAL!$C$5:$I$1115,5,0)) | C33: =IF($A33="","",VLOOKUP($A33,JOURNAL!$C$5:$I$1115,2,0)) | D33: =IF($A33="","",VLOOKUP($A33,JOURNAL!$C$5:$I$1115,4,0)) | E33: =IF($A33="","",VLOOKUP($A33,JOURNAL!$C$5:$I$1115,3,0))
A34: =IF(A33="","",IF(ISNA(VLOOKUP($A$1&" / "&$A$28,INDIRECT(ADDRESS(A33+5,2,1,,"JOURNAL")&":G700"),2,0)),"",VLOOKUP($A$1&" / "&$A$28,INDIRECT(ADDRESS(A33+5,2,1,,"JOURNAL")&":G700"),2,0))) | B34: =IF($A34="","",VLOOKUP($A34,JOURNAL!$C$5:$I$1115,5,0)) | C34: =IF($A34="","",VLOOKUP($A34,JOURNAL!$C$5:$I$1115,2,0)) | D34: =IF($A34="","",VLOOKUP($A34,JOURNAL!$C$5:$I$1115,4,0)) | E34: =IF($A34="","",VLOOKUP($A34,JOURNAL!$C$5:$I$1115,3,0))
A35: =IF(A34="","",IF(ISNA(VLOOKUP($A$1&" / "&$A$28,INDIRECT(ADDRESS(A34+5,2,1,,"JOURNAL")&":G700"),2,0)),"",VLOOKUP($A$1&" / "&$A$28,INDIRECT(ADDRESS(A34+5,2,1,,"JOURNAL")&":G700"),2,0))) | B35: =IF($A35="","",VLOOKUP($A35,JOURNAL!$C$5:$I$1115,5,0)) | C35: =IF($A35="","",VLOOKUP($A35,JOURNAL!$C$5:$I$1115,2,0)) | D35: =IF($A35="","",VLOOKUP($A35,JOURNAL!$C$5:$I$1115,4,0)) | E35: =IF($A35="","",VLOOKUP($A35,JOURNAL!$C$5:$I$1115,3,0))
